[2024-08-24T19:57:45.702+0000] {processor.py:186} INFO - Started process (PID=9375) to work on /opt/airflow/dags/dag_parquet_e_lotes.py
[2024-08-24T19:57:45.706+0000] {processor.py:914} INFO - Processing file /opt/airflow/dags/dag_parquet_e_lotes.py for tasks to queue
[2024-08-24T19:57:45.709+0000] {logging_mixin.py:190} INFO - [2024-08-24T19:57:45.708+0000] {dagbag.py:587} INFO - Filling up the DagBag from /opt/airflow/dags/dag_parquet_e_lotes.py
[2024-08-24T19:57:46.070+0000] {logging_mixin.py:190} INFO - [2024-08-24T19:57:46.011+0000] {dagbag.py:386} ERROR - Failed to import: /opt/airflow/dags/dag_parquet_e_lotes.py
Traceback (most recent call last):
  File "/home/airflow/.local/lib/python3.12/site-packages/airflow/models/dagbag.py", line 382, in parse
    loader.exec_module(new_module)
  File "<frozen importlib._bootstrap_external>", line 995, in exec_module
  File "<frozen importlib._bootstrap>", line 488, in _call_with_frames_removed
  File "/opt/airflow/dags/dag_parquet_e_lotes.py", line 7, in <module>
    from utils.manipular_parquet import manipular_parquet
ModuleNotFoundError: No module named 'utils.manipular_parquet'
[2024-08-24T19:57:46.078+0000] {processor.py:927} WARNING - No viable dags retrieved from /opt/airflow/dags/dag_parquet_e_lotes.py
[2024-08-24T19:57:46.261+0000] {processor.py:208} INFO - Processing /opt/airflow/dags/dag_parquet_e_lotes.py took 0.641 seconds
[2024-08-24T19:58:17.179+0000] {processor.py:186} INFO - Started process (PID=9439) to work on /opt/airflow/dags/dag_parquet_e_lotes.py
[2024-08-24T19:58:17.191+0000] {processor.py:914} INFO - Processing file /opt/airflow/dags/dag_parquet_e_lotes.py for tasks to queue
[2024-08-24T19:58:17.195+0000] {logging_mixin.py:190} INFO - [2024-08-24T19:58:17.194+0000] {dagbag.py:587} INFO - Filling up the DagBag from /opt/airflow/dags/dag_parquet_e_lotes.py
[2024-08-24T19:58:17.338+0000] {logging_mixin.py:190} INFO - [2024-08-24T19:58:17.330+0000] {dagbag.py:386} ERROR - Failed to import: /opt/airflow/dags/dag_parquet_e_lotes.py
Traceback (most recent call last):
  File "/home/airflow/.local/lib/python3.12/site-packages/airflow/models/dagbag.py", line 382, in parse
    loader.exec_module(new_module)
  File "<frozen importlib._bootstrap_external>", line 995, in exec_module
  File "<frozen importlib._bootstrap>", line 488, in _call_with_frames_removed
  File "/opt/airflow/dags/dag_parquet_e_lotes.py", line 7, in <module>
    from utils.manipular_parquet import manipular_parquet
ImportError: cannot import name 'manipular_parquet' from 'utils.manipular_parquet' (/opt/airflow/dags/utils/manipular_parquet.py)
[2024-08-24T19:58:17.342+0000] {processor.py:927} WARNING - No viable dags retrieved from /opt/airflow/dags/dag_parquet_e_lotes.py
[2024-08-24T19:58:17.404+0000] {processor.py:208} INFO - Processing /opt/airflow/dags/dag_parquet_e_lotes.py took 0.250 seconds
[2024-08-24T19:58:48.128+0000] {processor.py:186} INFO - Started process (PID=9500) to work on /opt/airflow/dags/dag_parquet_e_lotes.py
[2024-08-24T19:58:48.131+0000] {processor.py:914} INFO - Processing file /opt/airflow/dags/dag_parquet_e_lotes.py for tasks to queue
[2024-08-24T19:58:48.137+0000] {logging_mixin.py:190} INFO - [2024-08-24T19:58:48.136+0000] {dagbag.py:587} INFO - Filling up the DagBag from /opt/airflow/dags/dag_parquet_e_lotes.py
[2024-08-24T19:58:48.260+0000] {logging_mixin.py:190} INFO - [2024-08-24T19:58:48.250+0000] {dagbag.py:386} ERROR - Failed to import: /opt/airflow/dags/dag_parquet_e_lotes.py
Traceback (most recent call last):
  File "/home/airflow/.local/lib/python3.12/site-packages/airflow/models/dagbag.py", line 382, in parse
    loader.exec_module(new_module)
  File "<frozen importlib._bootstrap_external>", line 995, in exec_module
  File "<frozen importlib._bootstrap>", line 488, in _call_with_frames_removed
  File "/opt/airflow/dags/dag_parquet_e_lotes.py", line 8, in <module>
    from utils.processar_lotes import processar_lotes
ModuleNotFoundError: No module named 'utils.processar_lotes'
[2024-08-24T19:58:48.264+0000] {processor.py:927} WARNING - No viable dags retrieved from /opt/airflow/dags/dag_parquet_e_lotes.py
[2024-08-24T19:58:48.375+0000] {processor.py:208} INFO - Processing /opt/airflow/dags/dag_parquet_e_lotes.py took 0.264 seconds
[2024-08-24T19:59:19.040+0000] {processor.py:186} INFO - Started process (PID=9560) to work on /opt/airflow/dags/dag_parquet_e_lotes.py
[2024-08-24T19:59:19.042+0000] {processor.py:914} INFO - Processing file /opt/airflow/dags/dag_parquet_e_lotes.py for tasks to queue
[2024-08-24T19:59:19.050+0000] {logging_mixin.py:190} INFO - [2024-08-24T19:59:19.046+0000] {dagbag.py:587} INFO - Filling up the DagBag from /opt/airflow/dags/dag_parquet_e_lotes.py
[2024-08-24T19:59:19.212+0000] {logging_mixin.py:190} INFO - [2024-08-24T19:59:19.191+0000] {dagbag.py:386} ERROR - Failed to import: /opt/airflow/dags/dag_parquet_e_lotes.py
Traceback (most recent call last):
  File "/home/airflow/.local/lib/python3.12/site-packages/airflow/models/dagbag.py", line 382, in parse
    loader.exec_module(new_module)
  File "<frozen importlib._bootstrap_external>", line 995, in exec_module
  File "<frozen importlib._bootstrap>", line 488, in _call_with_frames_removed
  File "/opt/airflow/dags/dag_parquet_e_lotes.py", line 8, in <module>
    from utils.processar_lotes import processar_lotes
ModuleNotFoundError: No module named 'utils.processar_lotes'
[2024-08-24T19:59:19.224+0000] {processor.py:927} WARNING - No viable dags retrieved from /opt/airflow/dags/dag_parquet_e_lotes.py
[2024-08-24T19:59:19.435+0000] {processor.py:208} INFO - Processing /opt/airflow/dags/dag_parquet_e_lotes.py took 0.416 seconds
[2024-08-24T19:59:50.067+0000] {processor.py:186} INFO - Started process (PID=9622) to work on /opt/airflow/dags/dag_parquet_e_lotes.py
[2024-08-24T19:59:50.070+0000] {processor.py:914} INFO - Processing file /opt/airflow/dags/dag_parquet_e_lotes.py for tasks to queue
[2024-08-24T19:59:50.073+0000] {logging_mixin.py:190} INFO - [2024-08-24T19:59:50.072+0000] {dagbag.py:587} INFO - Filling up the DagBag from /opt/airflow/dags/dag_parquet_e_lotes.py
[2024-08-24T19:59:50.152+0000] {logging_mixin.py:190} INFO - [2024-08-24T19:59:50.145+0000] {dagbag.py:386} ERROR - Failed to import: /opt/airflow/dags/dag_parquet_e_lotes.py
Traceback (most recent call last):
  File "/home/airflow/.local/lib/python3.12/site-packages/airflow/models/dagbag.py", line 382, in parse
    loader.exec_module(new_module)
  File "<frozen importlib._bootstrap_external>", line 995, in exec_module
  File "<frozen importlib._bootstrap>", line 488, in _call_with_frames_removed
  File "/opt/airflow/dags/dag_parquet_e_lotes.py", line 8, in <module>
    from utils.processar_lotes import processar_lotes
ModuleNotFoundError: No module named 'utils.processar_lotes'
[2024-08-24T19:59:50.155+0000] {processor.py:927} WARNING - No viable dags retrieved from /opt/airflow/dags/dag_parquet_e_lotes.py
[2024-08-24T19:59:50.254+0000] {processor.py:208} INFO - Processing /opt/airflow/dags/dag_parquet_e_lotes.py took 0.205 seconds
[2024-08-24T20:00:21.092+0000] {processor.py:186} INFO - Started process (PID=9684) to work on /opt/airflow/dags/dag_parquet_e_lotes.py
[2024-08-24T20:00:21.095+0000] {processor.py:914} INFO - Processing file /opt/airflow/dags/dag_parquet_e_lotes.py for tasks to queue
[2024-08-24T20:00:21.098+0000] {logging_mixin.py:190} INFO - [2024-08-24T20:00:21.097+0000] {dagbag.py:587} INFO - Filling up the DagBag from /opt/airflow/dags/dag_parquet_e_lotes.py
[2024-08-24T20:00:21.162+0000] {logging_mixin.py:190} INFO - [2024-08-24T20:00:21.154+0000] {dagbag.py:386} ERROR - Failed to import: /opt/airflow/dags/dag_parquet_e_lotes.py
Traceback (most recent call last):
  File "/home/airflow/.local/lib/python3.12/site-packages/airflow/models/dagbag.py", line 382, in parse
    loader.exec_module(new_module)
  File "<frozen importlib._bootstrap_external>", line 995, in exec_module
  File "<frozen importlib._bootstrap>", line 488, in _call_with_frames_removed
  File "/opt/airflow/dags/dag_parquet_e_lotes.py", line 8, in <module>
    from utils.processar_lotes import processar_lotes
ModuleNotFoundError: No module named 'utils.processar_lotes'
[2024-08-24T20:00:21.165+0000] {processor.py:927} WARNING - No viable dags retrieved from /opt/airflow/dags/dag_parquet_e_lotes.py
[2024-08-24T20:00:21.254+0000] {processor.py:208} INFO - Processing /opt/airflow/dags/dag_parquet_e_lotes.py took 0.178 seconds
[2024-08-24T20:00:51.683+0000] {processor.py:186} INFO - Started process (PID=9745) to work on /opt/airflow/dags/dag_parquet_e_lotes.py
[2024-08-24T20:00:51.693+0000] {processor.py:914} INFO - Processing file /opt/airflow/dags/dag_parquet_e_lotes.py for tasks to queue
[2024-08-24T20:00:51.709+0000] {logging_mixin.py:190} INFO - [2024-08-24T20:00:51.708+0000] {dagbag.py:587} INFO - Filling up the DagBag from /opt/airflow/dags/dag_parquet_e_lotes.py
[2024-08-24T20:00:51.880+0000] {logging_mixin.py:190} INFO - [2024-08-24T20:00:51.866+0000] {dagbag.py:386} ERROR - Failed to import: /opt/airflow/dags/dag_parquet_e_lotes.py
Traceback (most recent call last):
  File "/home/airflow/.local/lib/python3.12/site-packages/airflow/models/dagbag.py", line 382, in parse
    loader.exec_module(new_module)
  File "<frozen importlib._bootstrap_external>", line 995, in exec_module
  File "<frozen importlib._bootstrap>", line 488, in _call_with_frames_removed
  File "/opt/airflow/dags/dag_parquet_e_lotes.py", line 8, in <module>
    from utils.processar_lotes import processar_lotes
ModuleNotFoundError: No module named 'utils.processar_lotes'
[2024-08-24T20:00:51.884+0000] {processor.py:927} WARNING - No viable dags retrieved from /opt/airflow/dags/dag_parquet_e_lotes.py
[2024-08-24T20:00:51.923+0000] {processor.py:208} INFO - Processing /opt/airflow/dags/dag_parquet_e_lotes.py took 0.310 seconds
[2024-08-24T20:01:23.311+0000] {processor.py:186} INFO - Started process (PID=9807) to work on /opt/airflow/dags/dag_parquet_e_lotes.py
[2024-08-24T20:01:23.313+0000] {processor.py:914} INFO - Processing file /opt/airflow/dags/dag_parquet_e_lotes.py for tasks to queue
[2024-08-24T20:01:23.317+0000] {logging_mixin.py:190} INFO - [2024-08-24T20:01:23.316+0000] {dagbag.py:587} INFO - Filling up the DagBag from /opt/airflow/dags/dag_parquet_e_lotes.py
[2024-08-24T20:01:23.405+0000] {logging_mixin.py:190} INFO - [2024-08-24T20:01:23.396+0000] {dagbag.py:386} ERROR - Failed to import: /opt/airflow/dags/dag_parquet_e_lotes.py
Traceback (most recent call last):
  File "/home/airflow/.local/lib/python3.12/site-packages/airflow/models/dagbag.py", line 382, in parse
    loader.exec_module(new_module)
  File "<frozen importlib._bootstrap_external>", line 995, in exec_module
  File "<frozen importlib._bootstrap>", line 488, in _call_with_frames_removed
  File "/opt/airflow/dags/dag_parquet_e_lotes.py", line 8, in <module>
    from utils.processar_lotes import processar_lotes
ModuleNotFoundError: No module named 'utils.processar_lotes'
[2024-08-24T20:01:23.409+0000] {processor.py:927} WARNING - No viable dags retrieved from /opt/airflow/dags/dag_parquet_e_lotes.py
[2024-08-24T20:01:23.473+0000] {processor.py:208} INFO - Processing /opt/airflow/dags/dag_parquet_e_lotes.py took 0.183 seconds
[2024-08-24T20:01:53.855+0000] {processor.py:186} INFO - Started process (PID=9870) to work on /opt/airflow/dags/dag_parquet_e_lotes.py
[2024-08-24T20:01:53.857+0000] {processor.py:914} INFO - Processing file /opt/airflow/dags/dag_parquet_e_lotes.py for tasks to queue
[2024-08-24T20:01:53.860+0000] {logging_mixin.py:190} INFO - [2024-08-24T20:01:53.860+0000] {dagbag.py:587} INFO - Filling up the DagBag from /opt/airflow/dags/dag_parquet_e_lotes.py
[2024-08-24T20:01:53.937+0000] {logging_mixin.py:190} INFO - [2024-08-24T20:01:53.929+0000] {dagbag.py:386} ERROR - Failed to import: /opt/airflow/dags/dag_parquet_e_lotes.py
Traceback (most recent call last):
  File "/home/airflow/.local/lib/python3.12/site-packages/airflow/models/dagbag.py", line 382, in parse
    loader.exec_module(new_module)
  File "<frozen importlib._bootstrap_external>", line 995, in exec_module
  File "<frozen importlib._bootstrap>", line 488, in _call_with_frames_removed
  File "/opt/airflow/dags/dag_parquet_e_lotes.py", line 8, in <module>
    from utils.processar_lotes import processar_lotes
ModuleNotFoundError: No module named 'utils.processar_lotes'
[2024-08-24T20:01:53.940+0000] {processor.py:927} WARNING - No viable dags retrieved from /opt/airflow/dags/dag_parquet_e_lotes.py
[2024-08-24T20:01:53.989+0000] {processor.py:208} INFO - Processing /opt/airflow/dags/dag_parquet_e_lotes.py took 0.148 seconds
[2024-08-24T20:02:18.614+0000] {processor.py:186} INFO - Started process (PID=9922) to work on /opt/airflow/dags/dag_parquet_e_lotes.py
[2024-08-24T20:02:18.618+0000] {processor.py:914} INFO - Processing file /opt/airflow/dags/dag_parquet_e_lotes.py for tasks to queue
[2024-08-24T20:02:18.635+0000] {logging_mixin.py:190} INFO - [2024-08-24T20:02:18.634+0000] {dagbag.py:587} INFO - Filling up the DagBag from /opt/airflow/dags/dag_parquet_e_lotes.py
[2024-08-24T20:02:19.333+0000] {logging_mixin.py:190} INFO - [2024-08-24T20:02:19.232+0000] {dagbag.py:386} ERROR - Failed to import: /opt/airflow/dags/dag_parquet_e_lotes.py
Traceback (most recent call last):
  File "/home/airflow/.local/lib/python3.12/site-packages/airflow/models/dagbag.py", line 382, in parse
    loader.exec_module(new_module)
  File "<frozen importlib._bootstrap_external>", line 995, in exec_module
  File "<frozen importlib._bootstrap>", line 488, in _call_with_frames_removed
  File "/opt/airflow/dags/dag_parquet_e_lotes.py", line 46, in <module>
    python_callable=processar_lotes
                    ^^^^^^^^^^^^^^^
NameError: name 'processar_lotes' is not defined
[2024-08-24T20:02:19.379+0000] {processor.py:927} WARNING - No viable dags retrieved from /opt/airflow/dags/dag_parquet_e_lotes.py
[2024-08-24T20:02:19.496+0000] {processor.py:208} INFO - Processing /opt/airflow/dags/dag_parquet_e_lotes.py took 0.927 seconds
[2024-08-24T20:02:36.810+0000] {processor.py:186} INFO - Started process (PID=9966) to work on /opt/airflow/dags/dag_parquet_e_lotes.py
[2024-08-24T20:02:36.821+0000] {processor.py:914} INFO - Processing file /opt/airflow/dags/dag_parquet_e_lotes.py for tasks to queue
[2024-08-24T20:02:36.833+0000] {logging_mixin.py:190} INFO - [2024-08-24T20:02:36.832+0000] {dagbag.py:587} INFO - Filling up the DagBag from /opt/airflow/dags/dag_parquet_e_lotes.py
[2024-08-24T20:02:37.054+0000] {logging_mixin.py:190} INFO - [2024-08-24T20:02:37.044+0000] {dagbag.py:386} ERROR - Failed to import: /opt/airflow/dags/dag_parquet_e_lotes.py
Traceback (most recent call last):
  File "/home/airflow/.local/lib/python3.12/site-packages/airflow/models/dagbag.py", line 382, in parse
    loader.exec_module(new_module)
  File "<frozen importlib._bootstrap_external>", line 995, in exec_module
  File "<frozen importlib._bootstrap>", line 488, in _call_with_frames_removed
  File "/opt/airflow/dags/dag_parquet_e_lotes.py", line 8, in <module>
    from utils2.verificar_novos_dados import verificar_novos_dados
ModuleNotFoundError: No module named 'utils2'
[2024-08-24T20:02:37.060+0000] {processor.py:927} WARNING - No viable dags retrieved from /opt/airflow/dags/dag_parquet_e_lotes.py
[2024-08-24T20:02:37.114+0000] {processor.py:208} INFO - Processing /opt/airflow/dags/dag_parquet_e_lotes.py took 0.344 seconds
[2024-08-24T20:02:39.310+0000] {processor.py:186} INFO - Started process (PID=9972) to work on /opt/airflow/dags/dag_parquet_e_lotes.py
[2024-08-24T20:02:39.314+0000] {processor.py:914} INFO - Processing file /opt/airflow/dags/dag_parquet_e_lotes.py for tasks to queue
[2024-08-24T20:02:39.327+0000] {logging_mixin.py:190} INFO - [2024-08-24T20:02:39.326+0000] {dagbag.py:587} INFO - Filling up the DagBag from /opt/airflow/dags/dag_parquet_e_lotes.py
[2024-08-24T20:02:39.576+0000] {logging_mixin.py:190} INFO - [2024-08-24T20:02:39.503+0000] {dagbag.py:386} ERROR - Failed to import: /opt/airflow/dags/dag_parquet_e_lotes.py
Traceback (most recent call last):
  File "/home/airflow/.local/lib/python3.12/site-packages/airflow/models/dagbag.py", line 382, in parse
    loader.exec_module(new_module)
  File "<frozen importlib._bootstrap_external>", line 995, in exec_module
  File "<frozen importlib._bootstrap>", line 488, in _call_with_frames_removed
  File "/opt/airflow/dags/dag_parquet_e_lotes.py", line 47, in <module>
    python_callable=processar_lotes
                    ^^^^^^^^^^^^^^^
NameError: name 'processar_lotes' is not defined
[2024-08-24T20:02:39.628+0000] {processor.py:927} WARNING - No viable dags retrieved from /opt/airflow/dags/dag_parquet_e_lotes.py
[2024-08-24T20:02:39.760+0000] {processor.py:208} INFO - Processing /opt/airflow/dags/dag_parquet_e_lotes.py took 0.482 seconds
[2024-08-24T20:02:42.901+0000] {processor.py:186} INFO - Started process (PID=9980) to work on /opt/airflow/dags/dag_parquet_e_lotes.py
[2024-08-24T20:02:42.903+0000] {processor.py:914} INFO - Processing file /opt/airflow/dags/dag_parquet_e_lotes.py for tasks to queue
[2024-08-24T20:02:42.906+0000] {logging_mixin.py:190} INFO - [2024-08-24T20:02:42.906+0000] {dagbag.py:587} INFO - Filling up the DagBag from /opt/airflow/dags/dag_parquet_e_lotes.py
[2024-08-24T20:02:43.055+0000] {logging_mixin.py:190} INFO - [2024-08-24T20:02:43.028+0000] {dagbag.py:386} ERROR - Failed to import: /opt/airflow/dags/dag_parquet_e_lotes.py
Traceback (most recent call last):
  File "/home/airflow/.local/lib/python3.12/site-packages/airflow/models/dagbag.py", line 382, in parse
    loader.exec_module(new_module)
  File "<frozen importlib._bootstrap_external>", line 995, in exec_module
  File "<frozen importlib._bootstrap>", line 488, in _call_with_frames_removed
  File "/opt/airflow/dags/dag_parquet_e_lotes.py", line 47, in <module>
    python_callable=processar_lotes
                    ^^^^^^^^^^^^^^^
NameError: name 'processar_lotes' is not defined
[2024-08-24T20:02:43.075+0000] {processor.py:927} WARNING - No viable dags retrieved from /opt/airflow/dags/dag_parquet_e_lotes.py
[2024-08-24T20:02:43.114+0000] {processor.py:208} INFO - Processing /opt/airflow/dags/dag_parquet_e_lotes.py took 0.228 seconds
[2024-08-24T20:03:03.861+0000] {processor.py:186} INFO - Started process (PID=10020) to work on /opt/airflow/dags/dag_parquet_e_lotes.py
[2024-08-24T20:03:03.879+0000] {processor.py:914} INFO - Processing file /opt/airflow/dags/dag_parquet_e_lotes.py for tasks to queue
[2024-08-24T20:03:03.883+0000] {logging_mixin.py:190} INFO - [2024-08-24T20:03:03.882+0000] {dagbag.py:587} INFO - Filling up the DagBag from /opt/airflow/dags/dag_parquet_e_lotes.py
[2024-08-24T20:03:04.168+0000] {logging_mixin.py:190} INFO - [2024-08-24T20:03:04.138+0000] {dagbag.py:386} ERROR - Failed to import: /opt/airflow/dags/dag_parquet_e_lotes.py
Traceback (most recent call last):
  File "/home/airflow/.local/lib/python3.12/site-packages/airflow/models/dagbag.py", line 382, in parse
    loader.exec_module(new_module)
  File "<frozen importlib._bootstrap_external>", line 995, in exec_module
  File "<frozen importlib._bootstrap>", line 488, in _call_with_frames_removed
  File "/opt/airflow/dags/dag_parquet_e_lotes.py", line 9, in <module>
    from utils2.carregar_no_bigquery import carregar_no_bigquery
ModuleNotFoundError: No module named 'utils2'
[2024-08-24T20:03:04.196+0000] {processor.py:927} WARNING - No viable dags retrieved from /opt/airflow/dags/dag_parquet_e_lotes.py
[2024-08-24T20:03:04.264+0000] {processor.py:208} INFO - Processing /opt/airflow/dags/dag_parquet_e_lotes.py took 0.442 seconds
[2024-08-24T20:03:05.399+0000] {processor.py:186} INFO - Started process (PID=10025) to work on /opt/airflow/dags/dag_parquet_e_lotes.py
[2024-08-24T20:03:05.428+0000] {processor.py:914} INFO - Processing file /opt/airflow/dags/dag_parquet_e_lotes.py for tasks to queue
[2024-08-24T20:03:05.440+0000] {logging_mixin.py:190} INFO - [2024-08-24T20:03:05.439+0000] {dagbag.py:587} INFO - Filling up the DagBag from /opt/airflow/dags/dag_parquet_e_lotes.py
[2024-08-24T20:03:06.093+0000] {logging_mixin.py:190} INFO - [2024-08-24T20:03:06.080+0000] {dagbag.py:386} ERROR - Failed to import: /opt/airflow/dags/dag_parquet_e_lotes.py
Traceback (most recent call last):
  File "/home/airflow/.local/lib/python3.12/site-packages/airflow/models/dagbag.py", line 382, in parse
    loader.exec_module(new_module)
  File "<frozen importlib._bootstrap_external>", line 995, in exec_module
  File "<frozen importlib._bootstrap>", line 488, in _call_with_frames_removed
  File "/opt/airflow/dags/dag_parquet_e_lotes.py", line 9, in <module>
    from utils.carregar_no_bigquery import carregar_no_bigquery
ModuleNotFoundError: No module named 'utils.carregar_no_bigquery'
[2024-08-24T20:03:06.204+0000] {processor.py:927} WARNING - No viable dags retrieved from /opt/airflow/dags/dag_parquet_e_lotes.py
[2024-08-24T20:03:06.430+0000] {processor.py:208} INFO - Processing /opt/airflow/dags/dag_parquet_e_lotes.py took 1.078 seconds
[2024-08-24T20:03:13.293+0000] {processor.py:186} INFO - Started process (PID=10041) to work on /opt/airflow/dags/dag_parquet_e_lotes.py
[2024-08-24T20:03:13.296+0000] {processor.py:914} INFO - Processing file /opt/airflow/dags/dag_parquet_e_lotes.py for tasks to queue
[2024-08-24T20:03:13.299+0000] {logging_mixin.py:190} INFO - [2024-08-24T20:03:13.298+0000] {dagbag.py:587} INFO - Filling up the DagBag from /opt/airflow/dags/dag_parquet_e_lotes.py
[2024-08-24T20:03:13.406+0000] {logging_mixin.py:190} INFO - [2024-08-24T20:03:13.397+0000] {dagbag.py:386} ERROR - Failed to import: /opt/airflow/dags/dag_parquet_e_lotes.py
Traceback (most recent call last):
  File "/home/airflow/.local/lib/python3.12/site-packages/airflow/models/dagbag.py", line 382, in parse
    loader.exec_module(new_module)
  File "<frozen importlib._bootstrap_external>", line 995, in exec_module
  File "<frozen importlib._bootstrap>", line 488, in _call_with_frames_removed
  File "/opt/airflow/dags/dag_parquet_e_lotes.py", line 9, in <module>
    from utils.carregar_no_postgre import carregar_no_bigquery
ModuleNotFoundError: No module named 'utils.carregar_no_postgre'
[2024-08-24T20:03:13.409+0000] {processor.py:927} WARNING - No viable dags retrieved from /opt/airflow/dags/dag_parquet_e_lotes.py
[2024-08-24T20:03:13.484+0000] {processor.py:208} INFO - Processing /opt/airflow/dags/dag_parquet_e_lotes.py took 0.211 seconds
[2024-08-24T20:03:15.928+0000] {processor.py:186} INFO - Started process (PID=10048) to work on /opt/airflow/dags/dag_parquet_e_lotes.py
[2024-08-24T20:03:15.942+0000] {processor.py:914} INFO - Processing file /opt/airflow/dags/dag_parquet_e_lotes.py for tasks to queue
[2024-08-24T20:03:15.951+0000] {logging_mixin.py:190} INFO - [2024-08-24T20:03:15.950+0000] {dagbag.py:587} INFO - Filling up the DagBag from /opt/airflow/dags/dag_parquet_e_lotes.py
[2024-08-24T20:03:19.233+0000] {logging_mixin.py:190} INFO - [2024-08-24T20:03:19.209+0000] {dagbag.py:386} ERROR - Failed to import: /opt/airflow/dags/dag_parquet_e_lotes.py
Traceback (most recent call last):
  File "/home/airflow/.local/lib/python3.12/site-packages/airflow/models/dagbag.py", line 382, in parse
    loader.exec_module(new_module)
  File "<frozen importlib._bootstrap_external>", line 995, in exec_module
  File "<frozen importlib._bootstrap>", line 488, in _call_with_frames_removed
  File "/opt/airflow/dags/dag_parquet_e_lotes.py", line 9, in <module>
    from utils.carregar_no_postgresql import carregar_no_bigquery
  File "/opt/airflow/dags/utils/carregar_no_postgresql.py", line 41, in <module>
    load_data_from_postgres_to_bigquery(pg_conn_string, bq_dataset, bq_table)
  File "/opt/airflow/dags/utils/carregar_no_postgresql.py", line 16, in load_data_from_postgres_to_bigquery
    conn = psycopg2.connect(pg_conn_string)
           ^^^^^^^^^^^^^^^^^^^^^^^^^^^^^^^^
  File "/home/airflow/.local/lib/python3.12/site-packages/psycopg2/__init__.py", line 122, in connect
    conn = _connect(dsn, connection_factory=connection_factory, **kwasync)
           ^^^^^^^^^^^^^^^^^^^^^^^^^^^^^^^^^^^^^^^^^^^^^^^^^^^^^^^^^^^^^^^
psycopg2.OperationalError: connection to server at "localhost" (::1), port 5432 failed: Connection refused
	Is the server running on that host and accepting TCP/IP connections?
connection to server at "localhost" (127.0.0.1), port 5432 failed: Connection refused
	Is the server running on that host and accepting TCP/IP connections?
[2024-08-24T20:03:19.241+0000] {processor.py:927} WARNING - No viable dags retrieved from /opt/airflow/dags/dag_parquet_e_lotes.py
[2024-08-24T20:03:19.292+0000] {processor.py:208} INFO - Processing /opt/airflow/dags/dag_parquet_e_lotes.py took 3.403 seconds
[2024-08-24T20:03:28.991+0000] {processor.py:186} INFO - Started process (PID=10069) to work on /opt/airflow/dags/dag_parquet_e_lotes.py
[2024-08-24T20:03:29.002+0000] {processor.py:914} INFO - Processing file /opt/airflow/dags/dag_parquet_e_lotes.py for tasks to queue
[2024-08-24T20:03:29.007+0000] {logging_mixin.py:190} INFO - [2024-08-24T20:03:29.006+0000] {dagbag.py:587} INFO - Filling up the DagBag from /opt/airflow/dags/dag_parquet_e_lotes.py
[2024-08-24T20:03:29.671+0000] {logging_mixin.py:190} INFO - [2024-08-24T20:03:29.655+0000] {dagbag.py:386} ERROR - Failed to import: /opt/airflow/dags/dag_parquet_e_lotes.py
Traceback (most recent call last):
  File "/home/airflow/.local/lib/python3.12/site-packages/airflow/models/dagbag.py", line 382, in parse
    loader.exec_module(new_module)
  File "<frozen importlib._bootstrap_external>", line 995, in exec_module
  File "<frozen importlib._bootstrap>", line 488, in _call_with_frames_removed
  File "/opt/airflow/dags/dag_parquet_e_lotes.py", line 9, in <module>
    from utils.carregar_no_postgresql import load_data_from_postgres_to_bigquery
  File "/opt/airflow/dags/utils/carregar_no_postgresql.py", line 41, in <module>
    load_data_from_postgres_to_bigquery(pg_conn_string, bq_dataset, bq_table)
  File "/opt/airflow/dags/utils/carregar_no_postgresql.py", line 16, in load_data_from_postgres_to_bigquery
    conn = psycopg2.connect(pg_conn_string)
           ^^^^^^^^^^^^^^^^^^^^^^^^^^^^^^^^
  File "/home/airflow/.local/lib/python3.12/site-packages/psycopg2/__init__.py", line 122, in connect
    conn = _connect(dsn, connection_factory=connection_factory, **kwasync)
           ^^^^^^^^^^^^^^^^^^^^^^^^^^^^^^^^^^^^^^^^^^^^^^^^^^^^^^^^^^^^^^^
psycopg2.OperationalError: connection to server at "localhost" (::1), port 5432 failed: Connection refused
	Is the server running on that host and accepting TCP/IP connections?
connection to server at "localhost" (127.0.0.1), port 5432 failed: Connection refused
	Is the server running on that host and accepting TCP/IP connections?
[2024-08-24T20:03:29.675+0000] {processor.py:927} WARNING - No viable dags retrieved from /opt/airflow/dags/dag_parquet_e_lotes.py
[2024-08-24T20:03:29.708+0000] {processor.py:208} INFO - Processing /opt/airflow/dags/dag_parquet_e_lotes.py took 0.737 seconds
[2024-08-24T20:03:59.936+0000] {processor.py:186} INFO - Started process (PID=10132) to work on /opt/airflow/dags/dag_parquet_e_lotes.py
[2024-08-24T20:03:59.938+0000] {processor.py:914} INFO - Processing file /opt/airflow/dags/dag_parquet_e_lotes.py for tasks to queue
[2024-08-24T20:03:59.941+0000] {logging_mixin.py:190} INFO - [2024-08-24T20:03:59.940+0000] {dagbag.py:587} INFO - Filling up the DagBag from /opt/airflow/dags/dag_parquet_e_lotes.py
[2024-08-24T20:04:00.442+0000] {logging_mixin.py:190} INFO - [2024-08-24T20:04:00.426+0000] {dagbag.py:386} ERROR - Failed to import: /opt/airflow/dags/dag_parquet_e_lotes.py
Traceback (most recent call last):
  File "/home/airflow/.local/lib/python3.12/site-packages/airflow/models/dagbag.py", line 382, in parse
    loader.exec_module(new_module)
  File "<frozen importlib._bootstrap_external>", line 995, in exec_module
  File "<frozen importlib._bootstrap>", line 488, in _call_with_frames_removed
  File "/opt/airflow/dags/dag_parquet_e_lotes.py", line 9, in <module>
    from utils.carregar_no_postgresql import load_data_from_postgres_to_bigquery
  File "/opt/airflow/dags/utils/carregar_no_postgresql.py", line 41, in <module>
    load_data_from_postgres_to_bigquery(pg_conn_string, bq_dataset, bq_table)
  File "/opt/airflow/dags/utils/carregar_no_postgresql.py", line 16, in load_data_from_postgres_to_bigquery
    conn = psycopg2.connect(pg_conn_string)
           ^^^^^^^^^^^^^^^^^^^^^^^^^^^^^^^^
  File "/home/airflow/.local/lib/python3.12/site-packages/psycopg2/__init__.py", line 122, in connect
    conn = _connect(dsn, connection_factory=connection_factory, **kwasync)
           ^^^^^^^^^^^^^^^^^^^^^^^^^^^^^^^^^^^^^^^^^^^^^^^^^^^^^^^^^^^^^^^
psycopg2.OperationalError: connection to server at "localhost" (::1), port 5432 failed: Connection refused
	Is the server running on that host and accepting TCP/IP connections?
connection to server at "localhost" (127.0.0.1), port 5432 failed: Connection refused
	Is the server running on that host and accepting TCP/IP connections?
[2024-08-24T20:04:00.445+0000] {processor.py:927} WARNING - No viable dags retrieved from /opt/airflow/dags/dag_parquet_e_lotes.py
[2024-08-24T20:04:00.483+0000] {processor.py:208} INFO - Processing /opt/airflow/dags/dag_parquet_e_lotes.py took 0.560 seconds
[2024-08-24T20:04:30.979+0000] {processor.py:186} INFO - Started process (PID=10195) to work on /opt/airflow/dags/dag_parquet_e_lotes.py
[2024-08-24T20:04:30.982+0000] {processor.py:914} INFO - Processing file /opt/airflow/dags/dag_parquet_e_lotes.py for tasks to queue
[2024-08-24T20:04:30.986+0000] {logging_mixin.py:190} INFO - [2024-08-24T20:04:30.985+0000] {dagbag.py:587} INFO - Filling up the DagBag from /opt/airflow/dags/dag_parquet_e_lotes.py
[2024-08-24T20:04:32.270+0000] {logging_mixin.py:190} INFO - [2024-08-24T20:04:32.247+0000] {dagbag.py:386} ERROR - Failed to import: /opt/airflow/dags/dag_parquet_e_lotes.py
Traceback (most recent call last):
  File "/home/airflow/.local/lib/python3.12/site-packages/airflow/models/dagbag.py", line 382, in parse
    loader.exec_module(new_module)
  File "<frozen importlib._bootstrap_external>", line 995, in exec_module
  File "<frozen importlib._bootstrap>", line 488, in _call_with_frames_removed
  File "/opt/airflow/dags/dag_parquet_e_lotes.py", line 9, in <module>
    from utils.carregar_no_postgresql import load_data_from_postgres_to_bigquery
  File "/opt/airflow/dags/utils/carregar_no_postgresql.py", line 41, in <module>
    load_data_from_postgres_to_bigquery(pg_conn_string, bq_dataset, bq_table)
  File "/opt/airflow/dags/utils/carregar_no_postgresql.py", line 16, in load_data_from_postgres_to_bigquery
    conn = psycopg2.connect(pg_conn_string)
           ^^^^^^^^^^^^^^^^^^^^^^^^^^^^^^^^
  File "/home/airflow/.local/lib/python3.12/site-packages/psycopg2/__init__.py", line 122, in connect
    conn = _connect(dsn, connection_factory=connection_factory, **kwasync)
           ^^^^^^^^^^^^^^^^^^^^^^^^^^^^^^^^^^^^^^^^^^^^^^^^^^^^^^^^^^^^^^^
psycopg2.OperationalError: connection to server at "localhost" (::1), port 5432 failed: Connection refused
	Is the server running on that host and accepting TCP/IP connections?
connection to server at "localhost" (127.0.0.1), port 5432 failed: Connection refused
	Is the server running on that host and accepting TCP/IP connections?
[2024-08-24T20:04:32.275+0000] {processor.py:927} WARNING - No viable dags retrieved from /opt/airflow/dags/dag_parquet_e_lotes.py
[2024-08-24T20:04:32.329+0000] {processor.py:208} INFO - Processing /opt/airflow/dags/dag_parquet_e_lotes.py took 1.366 seconds
[2024-08-24T20:04:35.631+0000] {processor.py:186} INFO - Started process (PID=10209) to work on /opt/airflow/dags/dag_parquet_e_lotes.py
[2024-08-24T20:04:35.640+0000] {processor.py:914} INFO - Processing file /opt/airflow/dags/dag_parquet_e_lotes.py for tasks to queue
[2024-08-24T20:04:35.646+0000] {logging_mixin.py:190} INFO - [2024-08-24T20:04:35.645+0000] {dagbag.py:587} INFO - Filling up the DagBag from /opt/airflow/dags/dag_parquet_e_lotes.py
[2024-08-24T20:04:35.697+0000] {logging_mixin.py:190} INFO - [2024-08-24T20:04:35.694+0000] {dagbag.py:386} ERROR - Failed to import: /opt/airflow/dags/dag_parquet_e_lotes.py
Traceback (most recent call last):
  File "/home/airflow/.local/lib/python3.12/site-packages/airflow/models/dagbag.py", line 382, in parse
    loader.exec_module(new_module)
  File "<frozen importlib._bootstrap_external>", line 991, in exec_module
  File "<frozen importlib._bootstrap_external>", line 1129, in get_code
  File "<frozen importlib._bootstrap_external>", line 1059, in source_to_code
  File "<frozen importlib._bootstrap>", line 488, in _call_with_frames_removed
  File "/opt/airflow/dags/dag_parquet_e_lotes.py", line 50
    baixar_parquet_task >> manipular_parquet_task >> processar_lotes_task extrair_dados_task >> transformar_dados_task >> carregar_dados_task
                                                                          ^^^^^^^^^^^^^^^^^^
SyntaxError: invalid syntax
[2024-08-24T20:04:35.700+0000] {processor.py:927} WARNING - No viable dags retrieved from /opt/airflow/dags/dag_parquet_e_lotes.py
[2024-08-24T20:04:35.799+0000] {processor.py:208} INFO - Processing /opt/airflow/dags/dag_parquet_e_lotes.py took 0.198 seconds
[2024-08-24T20:04:41.293+0000] {processor.py:186} INFO - Started process (PID=10222) to work on /opt/airflow/dags/dag_parquet_e_lotes.py
[2024-08-24T20:04:41.312+0000] {processor.py:914} INFO - Processing file /opt/airflow/dags/dag_parquet_e_lotes.py for tasks to queue
[2024-08-24T20:04:41.337+0000] {logging_mixin.py:190} INFO - [2024-08-24T20:04:41.336+0000] {dagbag.py:587} INFO - Filling up the DagBag from /opt/airflow/dags/dag_parquet_e_lotes.py
[2024-08-24T20:04:42.418+0000] {logging_mixin.py:190} INFO - [2024-08-24T20:04:42.398+0000] {dagbag.py:386} ERROR - Failed to import: /opt/airflow/dags/dag_parquet_e_lotes.py
Traceback (most recent call last):
  File "/home/airflow/.local/lib/python3.12/site-packages/airflow/models/dagbag.py", line 382, in parse
    loader.exec_module(new_module)
  File "<frozen importlib._bootstrap_external>", line 995, in exec_module
  File "<frozen importlib._bootstrap>", line 488, in _call_with_frames_removed
  File "/opt/airflow/dags/dag_parquet_e_lotes.py", line 9, in <module>
    from utils.carregar_no_postgresql import load_data_from_postgres_to_bigquery
  File "/opt/airflow/dags/utils/carregar_no_postgresql.py", line 41, in <module>
    load_data_from_postgres_to_bigquery(pg_conn_string, bq_dataset, bq_table)
  File "/opt/airflow/dags/utils/carregar_no_postgresql.py", line 16, in load_data_from_postgres_to_bigquery
    conn = psycopg2.connect(pg_conn_string)
           ^^^^^^^^^^^^^^^^^^^^^^^^^^^^^^^^
  File "/home/airflow/.local/lib/python3.12/site-packages/psycopg2/__init__.py", line 122, in connect
    conn = _connect(dsn, connection_factory=connection_factory, **kwasync)
           ^^^^^^^^^^^^^^^^^^^^^^^^^^^^^^^^^^^^^^^^^^^^^^^^^^^^^^^^^^^^^^^
psycopg2.OperationalError: connection to server at "localhost" (::1), port 5432 failed: Connection refused
	Is the server running on that host and accepting TCP/IP connections?
connection to server at "localhost" (127.0.0.1), port 5432 failed: Connection refused
	Is the server running on that host and accepting TCP/IP connections?
[2024-08-24T20:04:42.422+0000] {processor.py:927} WARNING - No viable dags retrieved from /opt/airflow/dags/dag_parquet_e_lotes.py
[2024-08-24T20:04:42.471+0000] {processor.py:208} INFO - Processing /opt/airflow/dags/dag_parquet_e_lotes.py took 1.215 seconds
[2024-08-24T20:05:12.788+0000] {processor.py:186} INFO - Started process (PID=10285) to work on /opt/airflow/dags/dag_parquet_e_lotes.py
[2024-08-24T20:05:12.792+0000] {processor.py:914} INFO - Processing file /opt/airflow/dags/dag_parquet_e_lotes.py for tasks to queue
[2024-08-24T20:05:12.798+0000] {logging_mixin.py:190} INFO - [2024-08-24T20:05:12.795+0000] {dagbag.py:587} INFO - Filling up the DagBag from /opt/airflow/dags/dag_parquet_e_lotes.py
[2024-08-24T20:05:13.416+0000] {logging_mixin.py:190} INFO - [2024-08-24T20:05:13.402+0000] {dagbag.py:386} ERROR - Failed to import: /opt/airflow/dags/dag_parquet_e_lotes.py
Traceback (most recent call last):
  File "/home/airflow/.local/lib/python3.12/site-packages/airflow/models/dagbag.py", line 382, in parse
    loader.exec_module(new_module)
  File "<frozen importlib._bootstrap_external>", line 995, in exec_module
  File "<frozen importlib._bootstrap>", line 488, in _call_with_frames_removed
  File "/opt/airflow/dags/dag_parquet_e_lotes.py", line 9, in <module>
    from utils.carregar_no_postgresql import load_data_from_postgres_to_bigquery
  File "/opt/airflow/dags/utils/carregar_no_postgresql.py", line 41, in <module>
    load_data_from_postgres_to_bigquery(pg_conn_string, bq_dataset, bq_table)
  File "/opt/airflow/dags/utils/carregar_no_postgresql.py", line 16, in load_data_from_postgres_to_bigquery
    conn = psycopg2.connect(pg_conn_string)
           ^^^^^^^^^^^^^^^^^^^^^^^^^^^^^^^^
  File "/home/airflow/.local/lib/python3.12/site-packages/psycopg2/__init__.py", line 122, in connect
    conn = _connect(dsn, connection_factory=connection_factory, **kwasync)
           ^^^^^^^^^^^^^^^^^^^^^^^^^^^^^^^^^^^^^^^^^^^^^^^^^^^^^^^^^^^^^^^
psycopg2.OperationalError: connection to server at "localhost" (::1), port 5432 failed: Connection refused
	Is the server running on that host and accepting TCP/IP connections?
connection to server at "localhost" (127.0.0.1), port 5432 failed: Connection refused
	Is the server running on that host and accepting TCP/IP connections?
[2024-08-24T20:05:13.420+0000] {processor.py:927} WARNING - No viable dags retrieved from /opt/airflow/dags/dag_parquet_e_lotes.py
[2024-08-24T20:05:13.457+0000] {processor.py:208} INFO - Processing /opt/airflow/dags/dag_parquet_e_lotes.py took 0.690 seconds
[2024-08-24T20:05:32.095+0000] {processor.py:186} INFO - Started process (PID=10322) to work on /opt/airflow/dags/dag_parquet_e_lotes.py
[2024-08-24T20:05:32.097+0000] {processor.py:914} INFO - Processing file /opt/airflow/dags/dag_parquet_e_lotes.py for tasks to queue
[2024-08-24T20:05:32.100+0000] {logging_mixin.py:190} INFO - [2024-08-24T20:05:32.100+0000] {dagbag.py:587} INFO - Filling up the DagBag from /opt/airflow/dags/dag_parquet_e_lotes.py
[2024-08-24T20:05:32.797+0000] {logging_mixin.py:190} INFO - [2024-08-24T20:05:32.781+0000] {dagbag.py:386} ERROR - Failed to import: /opt/airflow/dags/dag_parquet_e_lotes.py
Traceback (most recent call last):
  File "/home/airflow/.local/lib/python3.12/site-packages/airflow/models/dagbag.py", line 382, in parse
    loader.exec_module(new_module)
  File "<frozen importlib._bootstrap_external>", line 995, in exec_module
  File "<frozen importlib._bootstrap>", line 488, in _call_with_frames_removed
  File "/opt/airflow/dags/dag_parquet_e_lotes.py", line 9, in <module>
    from utils.carregar_no_postgresql import load_data_from_postgres_to_bigquery
  File "/opt/airflow/dags/utils/carregar_no_postgresql.py", line 41, in <module>
    load_data_from_postgres_to_bigquery(pg_conn_string, bq_dataset, bq_table)
  File "/opt/airflow/dags/utils/carregar_no_postgresql.py", line 16, in load_data_from_postgres_to_bigquery
    conn = psycopg2.connect(pg_conn_string)
           ^^^^^^^^^^^^^^^^^^^^^^^^^^^^^^^^
  File "/home/airflow/.local/lib/python3.12/site-packages/psycopg2/__init__.py", line 122, in connect
    conn = _connect(dsn, connection_factory=connection_factory, **kwasync)
           ^^^^^^^^^^^^^^^^^^^^^^^^^^^^^^^^^^^^^^^^^^^^^^^^^^^^^^^^^^^^^^^
psycopg2.OperationalError: connection to server at "localhost" (::1), port 5432 failed: Connection refused
	Is the server running on that host and accepting TCP/IP connections?
connection to server at "localhost" (127.0.0.1), port 5432 failed: Connection refused
	Is the server running on that host and accepting TCP/IP connections?
[2024-08-24T20:05:32.800+0000] {processor.py:927} WARNING - No viable dags retrieved from /opt/airflow/dags/dag_parquet_e_lotes.py
[2024-08-24T20:05:32.844+0000] {processor.py:208} INFO - Processing /opt/airflow/dags/dag_parquet_e_lotes.py took 0.774 seconds
[2024-08-24T20:05:34.261+0000] {processor.py:186} INFO - Started process (PID=10333) to work on /opt/airflow/dags/dag_parquet_e_lotes.py
[2024-08-24T20:05:34.268+0000] {processor.py:914} INFO - Processing file /opt/airflow/dags/dag_parquet_e_lotes.py for tasks to queue
[2024-08-24T20:05:34.271+0000] {logging_mixin.py:190} INFO - [2024-08-24T20:05:34.271+0000] {dagbag.py:587} INFO - Filling up the DagBag from /opt/airflow/dags/dag_parquet_e_lotes.py
[2024-08-24T20:05:35.163+0000] {logging_mixin.py:190} INFO - [2024-08-24T20:05:35.143+0000] {dagbag.py:386} ERROR - Failed to import: /opt/airflow/dags/dag_parquet_e_lotes.py
Traceback (most recent call last):
  File "/home/airflow/.local/lib/python3.12/site-packages/airflow/models/dagbag.py", line 382, in parse
    loader.exec_module(new_module)
  File "<frozen importlib._bootstrap_external>", line 995, in exec_module
  File "<frozen importlib._bootstrap>", line 488, in _call_with_frames_removed
  File "/opt/airflow/dags/dag_parquet_e_lotes.py", line 9, in <module>
    from utils.carregar_no_postgresql import load_data_from_postgres_to_bigquery
  File "/opt/airflow/dags/utils/carregar_no_postgresql.py", line 41, in <module>
    load_data_from_postgres_to_bigquery(pg_conn_string, bq_dataset, bq_table)
  File "/opt/airflow/dags/utils/carregar_no_postgresql.py", line 16, in load_data_from_postgres_to_bigquery
    conn = psycopg2.connect(pg_conn_string)
           ^^^^^^^^^^^^^^^^^^^^^^^^^^^^^^^^
  File "/home/airflow/.local/lib/python3.12/site-packages/psycopg2/__init__.py", line 122, in connect
    conn = _connect(dsn, connection_factory=connection_factory, **kwasync)
           ^^^^^^^^^^^^^^^^^^^^^^^^^^^^^^^^^^^^^^^^^^^^^^^^^^^^^^^^^^^^^^^
psycopg2.OperationalError: connection to server at "localhost" (::1), port 5432 failed: Connection refused
	Is the server running on that host and accepting TCP/IP connections?
connection to server at "localhost" (127.0.0.1), port 5432 failed: Connection refused
	Is the server running on that host and accepting TCP/IP connections?
[2024-08-24T20:05:35.167+0000] {processor.py:927} WARNING - No viable dags retrieved from /opt/airflow/dags/dag_parquet_e_lotes.py
[2024-08-24T20:05:35.240+0000] {processor.py:208} INFO - Processing /opt/airflow/dags/dag_parquet_e_lotes.py took 0.993 seconds
[2024-08-24T20:05:37.731+0000] {processor.py:186} INFO - Started process (PID=10338) to work on /opt/airflow/dags/dag_parquet_e_lotes.py
[2024-08-24T20:05:37.742+0000] {processor.py:914} INFO - Processing file /opt/airflow/dags/dag_parquet_e_lotes.py for tasks to queue
[2024-08-24T20:05:37.764+0000] {logging_mixin.py:190} INFO - [2024-08-24T20:05:37.763+0000] {dagbag.py:587} INFO - Filling up the DagBag from /opt/airflow/dags/dag_parquet_e_lotes.py
[2024-08-24T20:05:38.557+0000] {logging_mixin.py:190} INFO - [2024-08-24T20:05:38.532+0000] {dagbag.py:386} ERROR - Failed to import: /opt/airflow/dags/dag_parquet_e_lotes.py
Traceback (most recent call last):
  File "/home/airflow/.local/lib/python3.12/site-packages/airflow/models/dagbag.py", line 382, in parse
    loader.exec_module(new_module)
  File "<frozen importlib._bootstrap_external>", line 995, in exec_module
  File "<frozen importlib._bootstrap>", line 488, in _call_with_frames_removed
  File "/opt/airflow/dags/dag_parquet_e_lotes.py", line 9, in <module>
    from utils.carregar_no_postgresql import load_data_from_postgres_to_bigquery
  File "/opt/airflow/dags/utils/carregar_no_postgresql.py", line 41, in <module>
    load_data_from_postgres_to_bigquery(pg_conn_string, bq_dataset, bq_table)
  File "/opt/airflow/dags/utils/carregar_no_postgresql.py", line 16, in load_data_from_postgres_to_bigquery
    conn = psycopg2.connect(pg_conn_string)
           ^^^^^^^^^^^^^^^^^^^^^^^^^^^^^^^^
  File "/home/airflow/.local/lib/python3.12/site-packages/psycopg2/__init__.py", line 122, in connect
    conn = _connect(dsn, connection_factory=connection_factory, **kwasync)
           ^^^^^^^^^^^^^^^^^^^^^^^^^^^^^^^^^^^^^^^^^^^^^^^^^^^^^^^^^^^^^^^
psycopg2.OperationalError: connection to server at "localhost" (::1), port 5432 failed: Connection refused
	Is the server running on that host and accepting TCP/IP connections?
connection to server at "localhost" (127.0.0.1), port 5432 failed: Connection refused
	Is the server running on that host and accepting TCP/IP connections?
[2024-08-24T20:05:38.562+0000] {processor.py:927} WARNING - No viable dags retrieved from /opt/airflow/dags/dag_parquet_e_lotes.py
[2024-08-24T20:05:38.660+0000] {processor.py:208} INFO - Processing /opt/airflow/dags/dag_parquet_e_lotes.py took 0.965 seconds
[2024-08-24T20:05:44.271+0000] {processor.py:186} INFO - Started process (PID=10351) to work on /opt/airflow/dags/dag_parquet_e_lotes.py
[2024-08-24T20:05:44.275+0000] {processor.py:914} INFO - Processing file /opt/airflow/dags/dag_parquet_e_lotes.py for tasks to queue
[2024-08-24T20:05:44.278+0000] {logging_mixin.py:190} INFO - [2024-08-24T20:05:44.278+0000] {dagbag.py:587} INFO - Filling up the DagBag from /opt/airflow/dags/dag_parquet_e_lotes.py
[2024-08-24T20:05:45.762+0000] {logging_mixin.py:190} INFO - [2024-08-24T20:05:45.676+0000] {dagbag.py:386} ERROR - Failed to import: /opt/airflow/dags/dag_parquet_e_lotes.py
Traceback (most recent call last):
  File "/home/airflow/.local/lib/python3.12/site-packages/airflow/models/dagbag.py", line 382, in parse
    loader.exec_module(new_module)
  File "<frozen importlib._bootstrap_external>", line 995, in exec_module
  File "<frozen importlib._bootstrap>", line 488, in _call_with_frames_removed
  File "/opt/airflow/dags/dag_parquet_e_lotes.py", line 9, in <module>
    from utils.carregar_no_postgresql import load_data_from_postgres_to_bigquery
  File "/opt/airflow/dags/utils/carregar_no_postgresql.py", line 41, in <module>
    load_data_from_postgres_to_bigquery(pg_conn_string, bq_dataset, bq_table)
  File "/opt/airflow/dags/utils/carregar_no_postgresql.py", line 16, in load_data_from_postgres_to_bigquery
    conn = psycopg2.connect(pg_conn_string)
           ^^^^^^^^^^^^^^^^^^^^^^^^^^^^^^^^
  File "/home/airflow/.local/lib/python3.12/site-packages/psycopg2/__init__.py", line 122, in connect
    conn = _connect(dsn, connection_factory=connection_factory, **kwasync)
           ^^^^^^^^^^^^^^^^^^^^^^^^^^^^^^^^^^^^^^^^^^^^^^^^^^^^^^^^^^^^^^^
psycopg2.OperationalError: connection to server at "localhost" (::1), port 5432 failed: Connection refused
	Is the server running on that host and accepting TCP/IP connections?
connection to server at "localhost" (127.0.0.1), port 5432 failed: Connection refused
	Is the server running on that host and accepting TCP/IP connections?
[2024-08-24T20:05:45.795+0000] {processor.py:927} WARNING - No viable dags retrieved from /opt/airflow/dags/dag_parquet_e_lotes.py
[2024-08-24T20:05:45.905+0000] {processor.py:208} INFO - Processing /opt/airflow/dags/dag_parquet_e_lotes.py took 1.679 seconds
[2024-08-24T20:05:52.129+0000] {processor.py:186} INFO - Started process (PID=10373) to work on /opt/airflow/dags/dag_parquet_e_lotes.py
[2024-08-24T20:05:52.132+0000] {processor.py:914} INFO - Processing file /opt/airflow/dags/dag_parquet_e_lotes.py for tasks to queue
[2024-08-24T20:05:52.146+0000] {logging_mixin.py:190} INFO - [2024-08-24T20:05:52.142+0000] {dagbag.py:587} INFO - Filling up the DagBag from /opt/airflow/dags/dag_parquet_e_lotes.py
[2024-08-24T20:05:52.773+0000] {logging_mixin.py:190} INFO - [2024-08-24T20:05:52.758+0000] {dagbag.py:386} ERROR - Failed to import: /opt/airflow/dags/dag_parquet_e_lotes.py
Traceback (most recent call last):
  File "/home/airflow/.local/lib/python3.12/site-packages/airflow/models/dagbag.py", line 382, in parse
    loader.exec_module(new_module)
  File "<frozen importlib._bootstrap_external>", line 995, in exec_module
  File "<frozen importlib._bootstrap>", line 488, in _call_with_frames_removed
  File "/opt/airflow/dags/dag_parquet_e_lotes.py", line 9, in <module>
    from utils.carregar_no_postgresql import load_data_from_postgres_to_bigquery
  File "/opt/airflow/dags/utils/carregar_no_postgresql.py", line 41, in <module>
    load_data_from_postgres_to_bigquery(pg_conn_string, bq_dataset, bq_table)
  File "/opt/airflow/dags/utils/carregar_no_postgresql.py", line 16, in load_data_from_postgres_to_bigquery
    conn = psycopg2.connect(pg_conn_string)
           ^^^^^^^^^^^^^^^^^^^^^^^^^^^^^^^^
  File "/home/airflow/.local/lib/python3.12/site-packages/psycopg2/__init__.py", line 122, in connect
    conn = _connect(dsn, connection_factory=connection_factory, **kwasync)
           ^^^^^^^^^^^^^^^^^^^^^^^^^^^^^^^^^^^^^^^^^^^^^^^^^^^^^^^^^^^^^^^
psycopg2.OperationalError: connection to server at "localhost" (::1), port 5432 failed: Connection refused
	Is the server running on that host and accepting TCP/IP connections?
connection to server at "localhost" (127.0.0.1), port 5432 failed: Connection refused
	Is the server running on that host and accepting TCP/IP connections?
[2024-08-24T20:05:52.777+0000] {processor.py:927} WARNING - No viable dags retrieved from /opt/airflow/dags/dag_parquet_e_lotes.py
[2024-08-24T20:05:52.815+0000] {processor.py:208} INFO - Processing /opt/airflow/dags/dag_parquet_e_lotes.py took 0.706 seconds
[2024-08-24T20:05:55.012+0000] {processor.py:186} INFO - Started process (PID=10377) to work on /opt/airflow/dags/dag_parquet_e_lotes.py
[2024-08-24T20:05:55.032+0000] {processor.py:914} INFO - Processing file /opt/airflow/dags/dag_parquet_e_lotes.py for tasks to queue
[2024-08-24T20:05:55.036+0000] {logging_mixin.py:190} INFO - [2024-08-24T20:05:55.035+0000] {dagbag.py:587} INFO - Filling up the DagBag from /opt/airflow/dags/dag_parquet_e_lotes.py
[2024-08-24T20:05:56.785+0000] {logging_mixin.py:190} INFO - [2024-08-24T20:05:56.761+0000] {dagbag.py:386} ERROR - Failed to import: /opt/airflow/dags/dag_parquet_e_lotes.py
Traceback (most recent call last):
  File "/home/airflow/.local/lib/python3.12/site-packages/airflow/models/dagbag.py", line 382, in parse
    loader.exec_module(new_module)
  File "<frozen importlib._bootstrap_external>", line 995, in exec_module
  File "<frozen importlib._bootstrap>", line 488, in _call_with_frames_removed
  File "/opt/airflow/dags/dag_parquet_e_lotes.py", line 9, in <module>
    from utils.carregar_no_postgresql import load_data_from_postgres_to_bigquery
  File "/opt/airflow/dags/utils/carregar_no_postgresql.py", line 41, in <module>
    load_data_from_postgres_to_bigquery(pg_conn_string, bq_dataset, bq_table)
  File "/opt/airflow/dags/utils/carregar_no_postgresql.py", line 16, in load_data_from_postgres_to_bigquery
    conn = psycopg2.connect(pg_conn_string)
           ^^^^^^^^^^^^^^^^^^^^^^^^^^^^^^^^
  File "/home/airflow/.local/lib/python3.12/site-packages/psycopg2/__init__.py", line 122, in connect
    conn = _connect(dsn, connection_factory=connection_factory, **kwasync)
           ^^^^^^^^^^^^^^^^^^^^^^^^^^^^^^^^^^^^^^^^^^^^^^^^^^^^^^^^^^^^^^^
psycopg2.OperationalError: connection to server at "localhost" (::1), port 5432 failed: Connection refused
	Is the server running on that host and accepting TCP/IP connections?
connection to server at "localhost" (127.0.0.1), port 5432 failed: Connection refused
	Is the server running on that host and accepting TCP/IP connections?
[2024-08-24T20:05:56.789+0000] {processor.py:927} WARNING - No viable dags retrieved from /opt/airflow/dags/dag_parquet_e_lotes.py
[2024-08-24T20:05:56.842+0000] {processor.py:208} INFO - Processing /opt/airflow/dags/dag_parquet_e_lotes.py took 1.854 seconds
[2024-08-24T20:06:07.348+0000] {processor.py:186} INFO - Started process (PID=10403) to work on /opt/airflow/dags/dag_parquet_e_lotes.py
[2024-08-24T20:06:07.354+0000] {processor.py:914} INFO - Processing file /opt/airflow/dags/dag_parquet_e_lotes.py for tasks to queue
[2024-08-24T20:06:07.370+0000] {logging_mixin.py:190} INFO - [2024-08-24T20:06:07.369+0000] {dagbag.py:587} INFO - Filling up the DagBag from /opt/airflow/dags/dag_parquet_e_lotes.py
[2024-08-24T20:06:07.730+0000] {logging_mixin.py:190} INFO - [2024-08-24T20:06:07.727+0000] {dagbag.py:386} ERROR - Failed to import: /opt/airflow/dags/dag_parquet_e_lotes.py
Traceback (most recent call last):
  File "/home/airflow/.local/lib/python3.12/site-packages/airflow/models/dagbag.py", line 382, in parse
    loader.exec_module(new_module)
  File "<frozen importlib._bootstrap_external>", line 991, in exec_module
  File "<frozen importlib._bootstrap_external>", line 1129, in get_code
  File "<frozen importlib._bootstrap_external>", line 1059, in source_to_code
  File "<frozen importlib._bootstrap>", line 488, in _call_with_frames_removed
  File "/opt/airflow/dags/dag_parquet_e_lotes.py", line 50
    verificar_novos_dados_task = PythonOperator(
IndentationError: unexpected indent
[2024-08-24T20:06:07.734+0000] {processor.py:927} WARNING - No viable dags retrieved from /opt/airflow/dags/dag_parquet_e_lotes.py
[2024-08-24T20:06:07.832+0000] {processor.py:208} INFO - Processing /opt/airflow/dags/dag_parquet_e_lotes.py took 0.520 seconds
[2024-08-24T20:06:27.232+0000] {processor.py:186} INFO - Started process (PID=10443) to work on /opt/airflow/dags/dag_parquet_e_lotes.py
[2024-08-24T20:06:27.234+0000] {processor.py:914} INFO - Processing file /opt/airflow/dags/dag_parquet_e_lotes.py for tasks to queue
[2024-08-24T20:06:27.238+0000] {logging_mixin.py:190} INFO - [2024-08-24T20:06:27.237+0000] {dagbag.py:587} INFO - Filling up the DagBag from /opt/airflow/dags/dag_parquet_e_lotes.py
[2024-08-24T20:06:27.289+0000] {logging_mixin.py:190} INFO - [2024-08-24T20:06:27.287+0000] {dagbag.py:386} ERROR - Failed to import: /opt/airflow/dags/dag_parquet_e_lotes.py
Traceback (most recent call last):
  File "/home/airflow/.local/lib/python3.12/site-packages/airflow/models/dagbag.py", line 382, in parse
    loader.exec_module(new_module)
  File "<frozen importlib._bootstrap_external>", line 991, in exec_module
  File "<frozen importlib._bootstrap_external>", line 1129, in get_code
  File "<frozen importlib._bootstrap_external>", line 1059, in source_to_code
  File "<frozen importlib._bootstrap>", line 488, in _call_with_frames_removed
  File "/opt/airflow/dags/dag_parquet_e_lotes.py", line 50
    carre_task = PythonOperator(
IndentationError: unexpected indent
[2024-08-24T20:06:27.292+0000] {processor.py:927} WARNING - No viable dags retrieved from /opt/airflow/dags/dag_parquet_e_lotes.py
[2024-08-24T20:06:27.349+0000] {processor.py:208} INFO - Processing /opt/airflow/dags/dag_parquet_e_lotes.py took 0.139 seconds
[2024-08-24T20:06:30.090+0000] {processor.py:186} INFO - Started process (PID=10449) to work on /opt/airflow/dags/dag_parquet_e_lotes.py
[2024-08-24T20:06:30.093+0000] {processor.py:914} INFO - Processing file /opt/airflow/dags/dag_parquet_e_lotes.py for tasks to queue
[2024-08-24T20:06:30.096+0000] {logging_mixin.py:190} INFO - [2024-08-24T20:06:30.095+0000] {dagbag.py:587} INFO - Filling up the DagBag from /opt/airflow/dags/dag_parquet_e_lotes.py
[2024-08-24T20:06:30.128+0000] {logging_mixin.py:190} INFO - [2024-08-24T20:06:30.125+0000] {dagbag.py:386} ERROR - Failed to import: /opt/airflow/dags/dag_parquet_e_lotes.py
Traceback (most recent call last):
  File "/home/airflow/.local/lib/python3.12/site-packages/airflow/models/dagbag.py", line 382, in parse
    loader.exec_module(new_module)
  File "<frozen importlib._bootstrap_external>", line 991, in exec_module
  File "<frozen importlib._bootstrap_external>", line 1129, in get_code
  File "<frozen importlib._bootstrap_external>", line 1059, in source_to_code
  File "<frozen importlib._bootstrap>", line 488, in _call_with_frames_removed
  File "/opt/airflow/dags/dag_parquet_e_lotes.py", line 50
    carregar_task = PythonOperator(
IndentationError: unexpected indent
[2024-08-24T20:06:30.129+0000] {processor.py:927} WARNING - No viable dags retrieved from /opt/airflow/dags/dag_parquet_e_lotes.py
[2024-08-24T20:06:30.175+0000] {processor.py:208} INFO - Processing /opt/airflow/dags/dag_parquet_e_lotes.py took 0.100 seconds
[2024-08-24T20:06:33.665+0000] {processor.py:186} INFO - Started process (PID=10461) to work on /opt/airflow/dags/dag_parquet_e_lotes.py
[2024-08-24T20:06:33.668+0000] {processor.py:914} INFO - Processing file /opt/airflow/dags/dag_parquet_e_lotes.py for tasks to queue
[2024-08-24T20:06:33.672+0000] {logging_mixin.py:190} INFO - [2024-08-24T20:06:33.671+0000] {dagbag.py:587} INFO - Filling up the DagBag from /opt/airflow/dags/dag_parquet_e_lotes.py
[2024-08-24T20:06:33.720+0000] {logging_mixin.py:190} INFO - [2024-08-24T20:06:33.715+0000] {dagbag.py:386} ERROR - Failed to import: /opt/airflow/dags/dag_parquet_e_lotes.py
Traceback (most recent call last):
  File "/home/airflow/.local/lib/python3.12/site-packages/airflow/models/dagbag.py", line 382, in parse
    loader.exec_module(new_module)
  File "<frozen importlib._bootstrap_external>", line 991, in exec_module
  File "<frozen importlib._bootstrap_external>", line 1129, in get_code
  File "<frozen importlib._bootstrap_external>", line 1059, in source_to_code
  File "<frozen importlib._bootstrap>", line 488, in _call_with_frames_removed
  File "/opt/airflow/dags/dag_parquet_e_lotes.py", line 50
    carregar_no__task = PythonOperator(
IndentationError: unexpected indent
[2024-08-24T20:06:33.722+0000] {processor.py:927} WARNING - No viable dags retrieved from /opt/airflow/dags/dag_parquet_e_lotes.py
[2024-08-24T20:06:33.794+0000] {processor.py:208} INFO - Processing /opt/airflow/dags/dag_parquet_e_lotes.py took 0.156 seconds
[2024-08-24T20:06:35.308+0000] {processor.py:186} INFO - Started process (PID=10465) to work on /opt/airflow/dags/dag_parquet_e_lotes.py
[2024-08-24T20:06:35.310+0000] {processor.py:914} INFO - Processing file /opt/airflow/dags/dag_parquet_e_lotes.py for tasks to queue
[2024-08-24T20:06:35.314+0000] {logging_mixin.py:190} INFO - [2024-08-24T20:06:35.313+0000] {dagbag.py:587} INFO - Filling up the DagBag from /opt/airflow/dags/dag_parquet_e_lotes.py
[2024-08-24T20:06:35.360+0000] {logging_mixin.py:190} INFO - [2024-08-24T20:06:35.358+0000] {dagbag.py:386} ERROR - Failed to import: /opt/airflow/dags/dag_parquet_e_lotes.py
Traceback (most recent call last):
  File "/home/airflow/.local/lib/python3.12/site-packages/airflow/models/dagbag.py", line 382, in parse
    loader.exec_module(new_module)
  File "<frozen importlib._bootstrap_external>", line 991, in exec_module
  File "<frozen importlib._bootstrap_external>", line 1129, in get_code
  File "<frozen importlib._bootstrap_external>", line 1059, in source_to_code
  File "<frozen importlib._bootstrap>", line 488, in _call_with_frames_removed
  File "/opt/airflow/dags/dag_parquet_e_lotes.py", line 50
    carregar_no_postgre_task = PythonOperator(
IndentationError: unexpected indent
[2024-08-24T20:06:35.362+0000] {processor.py:927} WARNING - No viable dags retrieved from /opt/airflow/dags/dag_parquet_e_lotes.py
[2024-08-24T20:06:35.399+0000] {processor.py:208} INFO - Processing /opt/airflow/dags/dag_parquet_e_lotes.py took 0.107 seconds
[2024-08-24T20:06:37.521+0000] {processor.py:186} INFO - Started process (PID=10471) to work on /opt/airflow/dags/dag_parquet_e_lotes.py
[2024-08-24T20:06:37.523+0000] {processor.py:914} INFO - Processing file /opt/airflow/dags/dag_parquet_e_lotes.py for tasks to queue
[2024-08-24T20:06:37.527+0000] {logging_mixin.py:190} INFO - [2024-08-24T20:06:37.526+0000] {dagbag.py:587} INFO - Filling up the DagBag from /opt/airflow/dags/dag_parquet_e_lotes.py
[2024-08-24T20:06:37.552+0000] {logging_mixin.py:190} INFO - [2024-08-24T20:06:37.550+0000] {dagbag.py:386} ERROR - Failed to import: /opt/airflow/dags/dag_parquet_e_lotes.py
Traceback (most recent call last):
  File "/home/airflow/.local/lib/python3.12/site-packages/airflow/models/dagbag.py", line 382, in parse
    loader.exec_module(new_module)
  File "<frozen importlib._bootstrap_external>", line 991, in exec_module
  File "<frozen importlib._bootstrap_external>", line 1129, in get_code
  File "<frozen importlib._bootstrap_external>", line 1059, in source_to_code
  File "<frozen importlib._bootstrap>", line 488, in _call_with_frames_removed
  File "/opt/airflow/dags/dag_parquet_e_lotes.py", line 50
    carregar_no_postgresql_task = PythonOperator(
IndentationError: unexpected indent
[2024-08-24T20:06:37.554+0000] {processor.py:927} WARNING - No viable dags retrieved from /opt/airflow/dags/dag_parquet_e_lotes.py
[2024-08-24T20:06:37.590+0000] {processor.py:208} INFO - Processing /opt/airflow/dags/dag_parquet_e_lotes.py took 0.081 seconds
[2024-08-24T20:06:41.696+0000] {processor.py:186} INFO - Started process (PID=10480) to work on /opt/airflow/dags/dag_parquet_e_lotes.py
[2024-08-24T20:06:41.708+0000] {processor.py:914} INFO - Processing file /opt/airflow/dags/dag_parquet_e_lotes.py for tasks to queue
[2024-08-24T20:06:41.713+0000] {logging_mixin.py:190} INFO - [2024-08-24T20:06:41.712+0000] {dagbag.py:587} INFO - Filling up the DagBag from /opt/airflow/dags/dag_parquet_e_lotes.py
[2024-08-24T20:06:41.767+0000] {logging_mixin.py:190} INFO - [2024-08-24T20:06:41.764+0000] {dagbag.py:386} ERROR - Failed to import: /opt/airflow/dags/dag_parquet_e_lotes.py
Traceback (most recent call last):
  File "/home/airflow/.local/lib/python3.12/site-packages/airflow/models/dagbag.py", line 382, in parse
    loader.exec_module(new_module)
  File "<frozen importlib._bootstrap_external>", line 991, in exec_module
  File "<frozen importlib._bootstrap_external>", line 1129, in get_code
  File "<frozen importlib._bootstrap_external>", line 1059, in source_to_code
  File "<frozen importlib._bootstrap>", line 488, in _call_with_frames_removed
  File "/opt/airflow/dags/dag_parquet_e_lotes.py", line 50
    carregar_no_postgresql_task = PythonOperator(
IndentationError: unexpected indent
[2024-08-24T20:06:41.769+0000] {processor.py:927} WARNING - No viable dags retrieved from /opt/airflow/dags/dag_parquet_e_lotes.py
[2024-08-24T20:06:41.825+0000] {processor.py:208} INFO - Processing /opt/airflow/dags/dag_parquet_e_lotes.py took 0.165 seconds
[2024-08-24T20:06:43.634+0000] {processor.py:186} INFO - Started process (PID=10486) to work on /opt/airflow/dags/dag_parquet_e_lotes.py
[2024-08-24T20:06:43.660+0000] {processor.py:914} INFO - Processing file /opt/airflow/dags/dag_parquet_e_lotes.py for tasks to queue
[2024-08-24T20:06:43.668+0000] {logging_mixin.py:190} INFO - [2024-08-24T20:06:43.667+0000] {dagbag.py:587} INFO - Filling up the DagBag from /opt/airflow/dags/dag_parquet_e_lotes.py
[2024-08-24T20:06:43.703+0000] {logging_mixin.py:190} INFO - [2024-08-24T20:06:43.701+0000] {dagbag.py:386} ERROR - Failed to import: /opt/airflow/dags/dag_parquet_e_lotes.py
Traceback (most recent call last):
  File "/home/airflow/.local/lib/python3.12/site-packages/airflow/models/dagbag.py", line 382, in parse
    loader.exec_module(new_module)
  File "<frozen importlib._bootstrap_external>", line 991, in exec_module
  File "<frozen importlib._bootstrap_external>", line 1129, in get_code
  File "<frozen importlib._bootstrap_external>", line 1059, in source_to_code
  File "<frozen importlib._bootstrap>", line 488, in _call_with_frames_removed
  File "/opt/airflow/dags/dag_parquet_e_lotes.py", line 50
    carregar_no_postgresql_task = PythonOperator(
IndentationError: unexpected indent
[2024-08-24T20:06:43.705+0000] {processor.py:927} WARNING - No viable dags retrieved from /opt/airflow/dags/dag_parquet_e_lotes.py
[2024-08-24T20:06:43.748+0000] {processor.py:208} INFO - Processing /opt/airflow/dags/dag_parquet_e_lotes.py took 0.144 seconds
[2024-08-24T20:07:14.790+0000] {processor.py:186} INFO - Started process (PID=10548) to work on /opt/airflow/dags/dag_parquet_e_lotes.py
[2024-08-24T20:07:14.792+0000] {processor.py:914} INFO - Processing file /opt/airflow/dags/dag_parquet_e_lotes.py for tasks to queue
[2024-08-24T20:07:14.794+0000] {logging_mixin.py:190} INFO - [2024-08-24T20:07:14.793+0000] {dagbag.py:587} INFO - Filling up the DagBag from /opt/airflow/dags/dag_parquet_e_lotes.py
[2024-08-24T20:07:14.823+0000] {logging_mixin.py:190} INFO - [2024-08-24T20:07:14.821+0000] {dagbag.py:386} ERROR - Failed to import: /opt/airflow/dags/dag_parquet_e_lotes.py
Traceback (most recent call last):
  File "/home/airflow/.local/lib/python3.12/site-packages/airflow/models/dagbag.py", line 382, in parse
    loader.exec_module(new_module)
  File "<frozen importlib._bootstrap_external>", line 991, in exec_module
  File "<frozen importlib._bootstrap_external>", line 1129, in get_code
  File "<frozen importlib._bootstrap_external>", line 1059, in source_to_code
  File "<frozen importlib._bootstrap>", line 488, in _call_with_frames_removed
  File "/opt/airflow/dags/dag_parquet_e_lotes.py", line 50
    carregar_no_postgresql_task = PythonOperator(
IndentationError: unexpected indent
[2024-08-24T20:07:14.824+0000] {processor.py:927} WARNING - No viable dags retrieved from /opt/airflow/dags/dag_parquet_e_lotes.py
[2024-08-24T20:07:14.859+0000] {processor.py:208} INFO - Processing /opt/airflow/dags/dag_parquet_e_lotes.py took 0.082 seconds
[2024-08-24T20:07:46.026+0000] {processor.py:186} INFO - Started process (PID=10609) to work on /opt/airflow/dags/dag_parquet_e_lotes.py
[2024-08-24T20:07:46.029+0000] {processor.py:914} INFO - Processing file /opt/airflow/dags/dag_parquet_e_lotes.py for tasks to queue
[2024-08-24T20:07:46.032+0000] {logging_mixin.py:190} INFO - [2024-08-24T20:07:46.031+0000] {dagbag.py:587} INFO - Filling up the DagBag from /opt/airflow/dags/dag_parquet_e_lotes.py
[2024-08-24T20:07:46.066+0000] {logging_mixin.py:190} INFO - [2024-08-24T20:07:46.064+0000] {dagbag.py:386} ERROR - Failed to import: /opt/airflow/dags/dag_parquet_e_lotes.py
Traceback (most recent call last):
  File "/home/airflow/.local/lib/python3.12/site-packages/airflow/models/dagbag.py", line 382, in parse
    loader.exec_module(new_module)
  File "<frozen importlib._bootstrap_external>", line 991, in exec_module
  File "<frozen importlib._bootstrap_external>", line 1129, in get_code
  File "<frozen importlib._bootstrap_external>", line 1059, in source_to_code
  File "<frozen importlib._bootstrap>", line 488, in _call_with_frames_removed
  File "/opt/airflow/dags/dag_parquet_e_lotes.py", line 50
    carregar_no_postgresql_task = PythonOperator(
IndentationError: unexpected indent
[2024-08-24T20:07:46.068+0000] {processor.py:927} WARNING - No viable dags retrieved from /opt/airflow/dags/dag_parquet_e_lotes.py
[2024-08-24T20:07:46.115+0000] {processor.py:208} INFO - Processing /opt/airflow/dags/dag_parquet_e_lotes.py took 0.124 seconds
[2024-08-24T20:08:17.172+0000] {processor.py:186} INFO - Started process (PID=10672) to work on /opt/airflow/dags/dag_parquet_e_lotes.py
[2024-08-24T20:08:17.175+0000] {processor.py:914} INFO - Processing file /opt/airflow/dags/dag_parquet_e_lotes.py for tasks to queue
[2024-08-24T20:08:17.183+0000] {logging_mixin.py:190} INFO - [2024-08-24T20:08:17.178+0000] {dagbag.py:587} INFO - Filling up the DagBag from /opt/airflow/dags/dag_parquet_e_lotes.py
[2024-08-24T20:08:17.233+0000] {logging_mixin.py:190} INFO - [2024-08-24T20:08:17.230+0000] {dagbag.py:386} ERROR - Failed to import: /opt/airflow/dags/dag_parquet_e_lotes.py
Traceback (most recent call last):
  File "/home/airflow/.local/lib/python3.12/site-packages/airflow/models/dagbag.py", line 382, in parse
    loader.exec_module(new_module)
  File "<frozen importlib._bootstrap_external>", line 991, in exec_module
  File "<frozen importlib._bootstrap_external>", line 1129, in get_code
  File "<frozen importlib._bootstrap_external>", line 1059, in source_to_code
  File "<frozen importlib._bootstrap>", line 488, in _call_with_frames_removed
  File "/opt/airflow/dags/dag_parquet_e_lotes.py", line 50
    carregar_no_postgresql_task = PythonOperator(
IndentationError: unexpected indent
[2024-08-24T20:08:17.241+0000] {processor.py:927} WARNING - No viable dags retrieved from /opt/airflow/dags/dag_parquet_e_lotes.py
[2024-08-24T20:08:17.304+0000] {processor.py:208} INFO - Processing /opt/airflow/dags/dag_parquet_e_lotes.py took 0.156 seconds
[2024-08-24T20:08:27.719+0000] {processor.py:186} INFO - Started process (PID=10701) to work on /opt/airflow/dags/dag_parquet_e_lotes.py
[2024-08-24T20:08:27.727+0000] {processor.py:914} INFO - Processing file /opt/airflow/dags/dag_parquet_e_lotes.py for tasks to queue
[2024-08-24T20:08:27.731+0000] {logging_mixin.py:190} INFO - [2024-08-24T20:08:27.730+0000] {dagbag.py:587} INFO - Filling up the DagBag from /opt/airflow/dags/dag_parquet_e_lotes.py
[2024-08-24T20:08:27.813+0000] {logging_mixin.py:190} INFO - [2024-08-24T20:08:27.811+0000] {dagbag.py:386} ERROR - Failed to import: /opt/airflow/dags/dag_parquet_e_lotes.py
Traceback (most recent call last):
  File "/home/airflow/.local/lib/python3.12/site-packages/airflow/models/dagbag.py", line 382, in parse
    loader.exec_module(new_module)
  File "<frozen importlib._bootstrap_external>", line 991, in exec_module
  File "<frozen importlib._bootstrap_external>", line 1129, in get_code
  File "<frozen importlib._bootstrap_external>", line 1059, in source_to_code
  File "<frozen importlib._bootstrap>", line 488, in _call_with_frames_removed
  File "/opt/airflow/dags/dag_parquet_e_lotes.py", line 52
    carregar_no_postgresql_task = PythonOperator(
IndentationError: unexpected indent
[2024-08-24T20:08:27.818+0000] {processor.py:927} WARNING - No viable dags retrieved from /opt/airflow/dags/dag_parquet_e_lotes.py
[2024-08-24T20:08:27.888+0000] {processor.py:208} INFO - Processing /opt/airflow/dags/dag_parquet_e_lotes.py took 0.196 seconds
[2024-08-24T20:08:33.472+0000] {processor.py:186} INFO - Started process (PID=10708) to work on /opt/airflow/dags/dag_parquet_e_lotes.py
[2024-08-24T20:08:33.489+0000] {processor.py:914} INFO - Processing file /opt/airflow/dags/dag_parquet_e_lotes.py for tasks to queue
[2024-08-24T20:08:33.493+0000] {logging_mixin.py:190} INFO - [2024-08-24T20:08:33.492+0000] {dagbag.py:587} INFO - Filling up the DagBag from /opt/airflow/dags/dag_parquet_e_lotes.py
[2024-08-24T20:08:33.559+0000] {logging_mixin.py:190} INFO - [2024-08-24T20:08:33.556+0000] {dagbag.py:386} ERROR - Failed to import: /opt/airflow/dags/dag_parquet_e_lotes.py
Traceback (most recent call last):
  File "/home/airflow/.local/lib/python3.12/site-packages/airflow/models/dagbag.py", line 382, in parse
    loader.exec_module(new_module)
  File "<frozen importlib._bootstrap_external>", line 991, in exec_module
  File "<frozen importlib._bootstrap_external>", line 1129, in get_code
  File "<frozen importlib._bootstrap_external>", line 1059, in source_to_code
  File "<frozen importlib._bootstrap>", line 488, in _call_with_frames_removed
  File "/opt/airflow/dags/dag_parquet_e_lotes.py", line 51
    carregar_no_postgresql_task = PythonOperator(
IndentationError: unexpected indent
[2024-08-24T20:08:33.562+0000] {processor.py:927} WARNING - No viable dags retrieved from /opt/airflow/dags/dag_parquet_e_lotes.py
[2024-08-24T20:08:33.645+0000] {processor.py:208} INFO - Processing /opt/airflow/dags/dag_parquet_e_lotes.py took 0.192 seconds
[2024-08-24T20:08:53.189+0000] {processor.py:186} INFO - Started process (PID=10748) to work on /opt/airflow/dags/dag_parquet_e_lotes.py
[2024-08-24T20:08:53.191+0000] {processor.py:914} INFO - Processing file /opt/airflow/dags/dag_parquet_e_lotes.py for tasks to queue
[2024-08-24T20:08:53.195+0000] {logging_mixin.py:190} INFO - [2024-08-24T20:08:53.194+0000] {dagbag.py:587} INFO - Filling up the DagBag from /opt/airflow/dags/dag_parquet_e_lotes.py
[2024-08-24T20:08:53.233+0000] {logging_mixin.py:190} INFO - [2024-08-24T20:08:53.231+0000] {dagbag.py:386} ERROR - Failed to import: /opt/airflow/dags/dag_parquet_e_lotes.py
Traceback (most recent call last):
  File "/home/airflow/.local/lib/python3.12/site-packages/airflow/models/dagbag.py", line 382, in parse
    loader.exec_module(new_module)
  File "<frozen importlib._bootstrap_external>", line 991, in exec_module
  File "<frozen importlib._bootstrap_external>", line 1129, in get_code
  File "<frozen importlib._bootstrap_external>", line 1059, in source_to_code
  File "<frozen importlib._bootstrap>", line 488, in _call_with_frames_removed
  File "/opt/airflow/dags/dag_parquet_e_lotes.py", line 64
    carregar_no_postgresql_task = PythonOperator(
IndentationError: unexpected indent
[2024-08-24T20:08:53.235+0000] {processor.py:927} WARNING - No viable dags retrieved from /opt/airflow/dags/dag_parquet_e_lotes.py
[2024-08-24T20:08:53.277+0000] {processor.py:208} INFO - Processing /opt/airflow/dags/dag_parquet_e_lotes.py took 0.117 seconds
[2024-08-24T20:09:16.427+0000] {processor.py:186} INFO - Started process (PID=10796) to work on /opt/airflow/dags/dag_parquet_e_lotes.py
[2024-08-24T20:09:16.439+0000] {processor.py:914} INFO - Processing file /opt/airflow/dags/dag_parquet_e_lotes.py for tasks to queue
[2024-08-24T20:09:16.450+0000] {logging_mixin.py:190} INFO - [2024-08-24T20:09:16.449+0000] {dagbag.py:587} INFO - Filling up the DagBag from /opt/airflow/dags/dag_parquet_e_lotes.py
[2024-08-24T20:09:16.505+0000] {logging_mixin.py:190} INFO - [2024-08-24T20:09:16.502+0000] {dagbag.py:386} ERROR - Failed to import: /opt/airflow/dags/dag_parquet_e_lotes.py
Traceback (most recent call last):
  File "/home/airflow/.local/lib/python3.12/site-packages/airflow/models/dagbag.py", line 382, in parse
    loader.exec_module(new_module)
  File "<frozen importlib._bootstrap_external>", line 991, in exec_module
  File "<frozen importlib._bootstrap_external>", line 1129, in get_code
  File "<frozen importlib._bootstrap_external>", line 1059, in source_to_code
  File "<frozen importlib._bootstrap>", line 488, in _call_with_frames_removed
  File "/opt/airflow/dags/dag_parquet_e_lotes.py", line 66
    carregar_no_postgresql_task = PythonOperator(
IndentationError: unexpected indent
[2024-08-24T20:09:16.508+0000] {processor.py:927} WARNING - No viable dags retrieved from /opt/airflow/dags/dag_parquet_e_lotes.py
[2024-08-24T20:09:16.625+0000] {processor.py:208} INFO - Processing /opt/airflow/dags/dag_parquet_e_lotes.py took 0.232 seconds
[2024-08-24T20:09:46.806+0000] {processor.py:186} INFO - Started process (PID=10860) to work on /opt/airflow/dags/dag_parquet_e_lotes.py
[2024-08-24T20:09:46.810+0000] {processor.py:914} INFO - Processing file /opt/airflow/dags/dag_parquet_e_lotes.py for tasks to queue
[2024-08-24T20:09:46.816+0000] {logging_mixin.py:190} INFO - [2024-08-24T20:09:46.815+0000] {dagbag.py:587} INFO - Filling up the DagBag from /opt/airflow/dags/dag_parquet_e_lotes.py
[2024-08-24T20:09:46.877+0000] {logging_mixin.py:190} INFO - [2024-08-24T20:09:46.875+0000] {dagbag.py:386} ERROR - Failed to import: /opt/airflow/dags/dag_parquet_e_lotes.py
Traceback (most recent call last):
  File "/home/airflow/.local/lib/python3.12/site-packages/airflow/models/dagbag.py", line 382, in parse
    loader.exec_module(new_module)
  File "<frozen importlib._bootstrap_external>", line 991, in exec_module
  File "<frozen importlib._bootstrap_external>", line 1129, in get_code
  File "<frozen importlib._bootstrap_external>", line 1059, in source_to_code
  File "<frozen importlib._bootstrap>", line 488, in _call_with_frames_removed
  File "/opt/airflow/dags/dag_parquet_e_lotes.py", line 66
    carregar_no_postgresql_task = PythonOperator(
IndentationError: unexpected indent
[2024-08-24T20:09:46.879+0000] {processor.py:927} WARNING - No viable dags retrieved from /opt/airflow/dags/dag_parquet_e_lotes.py
[2024-08-24T20:09:46.921+0000] {processor.py:208} INFO - Processing /opt/airflow/dags/dag_parquet_e_lotes.py took 0.138 seconds
[2024-08-24T20:10:17.702+0000] {processor.py:186} INFO - Started process (PID=10922) to work on /opt/airflow/dags/dag_parquet_e_lotes.py
[2024-08-24T20:10:17.721+0000] {processor.py:914} INFO - Processing file /opt/airflow/dags/dag_parquet_e_lotes.py for tasks to queue
[2024-08-24T20:10:17.725+0000] {logging_mixin.py:190} INFO - [2024-08-24T20:10:17.724+0000] {dagbag.py:587} INFO - Filling up the DagBag from /opt/airflow/dags/dag_parquet_e_lotes.py
[2024-08-24T20:10:17.934+0000] {logging_mixin.py:190} INFO - [2024-08-24T20:10:17.931+0000] {dagbag.py:386} ERROR - Failed to import: /opt/airflow/dags/dag_parquet_e_lotes.py
Traceback (most recent call last):
  File "/home/airflow/.local/lib/python3.12/site-packages/airflow/models/dagbag.py", line 382, in parse
    loader.exec_module(new_module)
  File "<frozen importlib._bootstrap_external>", line 991, in exec_module
  File "<frozen importlib._bootstrap_external>", line 1129, in get_code
  File "<frozen importlib._bootstrap_external>", line 1059, in source_to_code
  File "<frozen importlib._bootstrap>", line 488, in _call_with_frames_removed
  File "/opt/airflow/dags/dag_parquet_e_lotes.py", line 66
    carregar_no_postgresql_task = PythonOperator(
IndentationError: unexpected indent
[2024-08-24T20:10:17.938+0000] {processor.py:927} WARNING - No viable dags retrieved from /opt/airflow/dags/dag_parquet_e_lotes.py
[2024-08-24T20:10:18.066+0000] {processor.py:208} INFO - Processing /opt/airflow/dags/dag_parquet_e_lotes.py took 0.386 seconds
[2024-08-24T20:10:48.642+0000] {processor.py:186} INFO - Started process (PID=10985) to work on /opt/airflow/dags/dag_parquet_e_lotes.py
[2024-08-24T20:10:48.644+0000] {processor.py:914} INFO - Processing file /opt/airflow/dags/dag_parquet_e_lotes.py for tasks to queue
[2024-08-24T20:10:48.650+0000] {logging_mixin.py:190} INFO - [2024-08-24T20:10:48.649+0000] {dagbag.py:587} INFO - Filling up the DagBag from /opt/airflow/dags/dag_parquet_e_lotes.py
[2024-08-24T20:10:48.705+0000] {logging_mixin.py:190} INFO - [2024-08-24T20:10:48.703+0000] {dagbag.py:386} ERROR - Failed to import: /opt/airflow/dags/dag_parquet_e_lotes.py
Traceback (most recent call last):
  File "/home/airflow/.local/lib/python3.12/site-packages/airflow/models/dagbag.py", line 382, in parse
    loader.exec_module(new_module)
  File "<frozen importlib._bootstrap_external>", line 991, in exec_module
  File "<frozen importlib._bootstrap_external>", line 1129, in get_code
  File "<frozen importlib._bootstrap_external>", line 1059, in source_to_code
  File "<frozen importlib._bootstrap>", line 488, in _call_with_frames_removed
  File "/opt/airflow/dags/dag_parquet_e_lotes.py", line 66
    carregar_no_postgresql_task = PythonOperator(
IndentationError: unexpected indent
[2024-08-24T20:10:48.708+0000] {processor.py:927} WARNING - No viable dags retrieved from /opt/airflow/dags/dag_parquet_e_lotes.py
[2024-08-24T20:10:48.755+0000] {processor.py:208} INFO - Processing /opt/airflow/dags/dag_parquet_e_lotes.py took 0.129 seconds
[2024-08-24T20:11:18.917+0000] {processor.py:186} INFO - Started process (PID=11047) to work on /opt/airflow/dags/dag_parquet_e_lotes.py
[2024-08-24T20:11:18.920+0000] {processor.py:914} INFO - Processing file /opt/airflow/dags/dag_parquet_e_lotes.py for tasks to queue
[2024-08-24T20:11:18.926+0000] {logging_mixin.py:190} INFO - [2024-08-24T20:11:18.925+0000] {dagbag.py:587} INFO - Filling up the DagBag from /opt/airflow/dags/dag_parquet_e_lotes.py
[2024-08-24T20:11:18.966+0000] {logging_mixin.py:190} INFO - [2024-08-24T20:11:18.964+0000] {dagbag.py:386} ERROR - Failed to import: /opt/airflow/dags/dag_parquet_e_lotes.py
Traceback (most recent call last):
  File "/home/airflow/.local/lib/python3.12/site-packages/airflow/models/dagbag.py", line 382, in parse
    loader.exec_module(new_module)
  File "<frozen importlib._bootstrap_external>", line 991, in exec_module
  File "<frozen importlib._bootstrap_external>", line 1129, in get_code
  File "<frozen importlib._bootstrap_external>", line 1059, in source_to_code
  File "<frozen importlib._bootstrap>", line 488, in _call_with_frames_removed
  File "/opt/airflow/dags/dag_parquet_e_lotes.py", line 66
    carregar_no_postgresql_task = PythonOperator(
IndentationError: unexpected indent
[2024-08-24T20:11:18.968+0000] {processor.py:927} WARNING - No viable dags retrieved from /opt/airflow/dags/dag_parquet_e_lotes.py
[2024-08-24T20:11:19.013+0000] {processor.py:208} INFO - Processing /opt/airflow/dags/dag_parquet_e_lotes.py took 0.114 seconds
[2024-08-24T20:11:22.978+0000] {processor.py:186} INFO - Started process (PID=11053) to work on /opt/airflow/dags/dag_parquet_e_lotes.py
[2024-08-24T20:11:22.983+0000] {processor.py:914} INFO - Processing file /opt/airflow/dags/dag_parquet_e_lotes.py for tasks to queue
[2024-08-24T20:11:22.989+0000] {logging_mixin.py:190} INFO - [2024-08-24T20:11:22.988+0000] {dagbag.py:587} INFO - Filling up the DagBag from /opt/airflow/dags/dag_parquet_e_lotes.py
[2024-08-24T20:11:23.154+0000] {logging_mixin.py:190} INFO - [2024-08-24T20:11:23.152+0000] {dagbag.py:386} ERROR - Failed to import: /opt/airflow/dags/dag_parquet_e_lotes.py
Traceback (most recent call last):
  File "/home/airflow/.local/lib/python3.12/site-packages/airflow/models/dagbag.py", line 382, in parse
    loader.exec_module(new_module)
  File "<frozen importlib._bootstrap_external>", line 991, in exec_module
  File "<frozen importlib._bootstrap_external>", line 1129, in get_code
  File "<frozen importlib._bootstrap_external>", line 1059, in source_to_code
  File "<frozen importlib._bootstrap>", line 488, in _call_with_frames_removed
  File "/opt/airflow/dags/dag_parquet_e_lotes.py", line 67
    carregar_no_postgresql_task = PythonOperator(
IndentationError: unexpected indent
[2024-08-24T20:11:23.157+0000] {processor.py:927} WARNING - No viable dags retrieved from /opt/airflow/dags/dag_parquet_e_lotes.py
[2024-08-24T20:11:23.233+0000] {processor.py:208} INFO - Processing /opt/airflow/dags/dag_parquet_e_lotes.py took 0.289 seconds
[2024-08-24T20:11:53.172+0000] {processor.py:186} INFO - Started process (PID=11116) to work on /opt/airflow/dags/dag_parquet_e_lotes.py
[2024-08-24T20:11:53.184+0000] {processor.py:914} INFO - Processing file /opt/airflow/dags/dag_parquet_e_lotes.py for tasks to queue
[2024-08-24T20:11:53.198+0000] {logging_mixin.py:190} INFO - [2024-08-24T20:11:53.198+0000] {dagbag.py:587} INFO - Filling up the DagBag from /opt/airflow/dags/dag_parquet_e_lotes.py
[2024-08-24T20:11:53.365+0000] {logging_mixin.py:190} INFO - [2024-08-24T20:11:53.362+0000] {dagbag.py:386} ERROR - Failed to import: /opt/airflow/dags/dag_parquet_e_lotes.py
Traceback (most recent call last):
  File "/home/airflow/.local/lib/python3.12/site-packages/airflow/models/dagbag.py", line 382, in parse
    loader.exec_module(new_module)
  File "<frozen importlib._bootstrap_external>", line 991, in exec_module
  File "<frozen importlib._bootstrap_external>", line 1129, in get_code
  File "<frozen importlib._bootstrap_external>", line 1059, in source_to_code
  File "<frozen importlib._bootstrap>", line 488, in _call_with_frames_removed
  File "/opt/airflow/dags/dag_parquet_e_lotes.py", line 67
    carregar_no_postgresql_task = PythonOperator(
IndentationError: unexpected indent
[2024-08-24T20:11:53.367+0000] {processor.py:927} WARNING - No viable dags retrieved from /opt/airflow/dags/dag_parquet_e_lotes.py
[2024-08-24T20:11:53.482+0000] {processor.py:208} INFO - Processing /opt/airflow/dags/dag_parquet_e_lotes.py took 0.346 seconds
[2024-08-24T20:12:24.010+0000] {processor.py:186} INFO - Started process (PID=11178) to work on /opt/airflow/dags/dag_parquet_e_lotes.py
[2024-08-24T20:12:24.012+0000] {processor.py:914} INFO - Processing file /opt/airflow/dags/dag_parquet_e_lotes.py for tasks to queue
[2024-08-24T20:12:24.015+0000] {logging_mixin.py:190} INFO - [2024-08-24T20:12:24.014+0000] {dagbag.py:587} INFO - Filling up the DagBag from /opt/airflow/dags/dag_parquet_e_lotes.py
[2024-08-24T20:12:24.051+0000] {logging_mixin.py:190} INFO - [2024-08-24T20:12:24.048+0000] {dagbag.py:386} ERROR - Failed to import: /opt/airflow/dags/dag_parquet_e_lotes.py
Traceback (most recent call last):
  File "/home/airflow/.local/lib/python3.12/site-packages/airflow/models/dagbag.py", line 382, in parse
    loader.exec_module(new_module)
  File "<frozen importlib._bootstrap_external>", line 991, in exec_module
  File "<frozen importlib._bootstrap_external>", line 1129, in get_code
  File "<frozen importlib._bootstrap_external>", line 1059, in source_to_code
  File "<frozen importlib._bootstrap>", line 488, in _call_with_frames_removed
  File "/opt/airflow/dags/dag_parquet_e_lotes.py", line 67
    carregar_no_postgresql_task = PythonOperator(
IndentationError: unexpected indent
[2024-08-24T20:12:24.053+0000] {processor.py:927} WARNING - No viable dags retrieved from /opt/airflow/dags/dag_parquet_e_lotes.py
[2024-08-24T20:12:24.109+0000] {processor.py:208} INFO - Processing /opt/airflow/dags/dag_parquet_e_lotes.py took 0.117 seconds
[2024-08-24T20:12:54.284+0000] {processor.py:186} INFO - Started process (PID=11240) to work on /opt/airflow/dags/dag_parquet_e_lotes.py
[2024-08-24T20:12:54.285+0000] {processor.py:914} INFO - Processing file /opt/airflow/dags/dag_parquet_e_lotes.py for tasks to queue
[2024-08-24T20:12:54.288+0000] {logging_mixin.py:190} INFO - [2024-08-24T20:12:54.287+0000] {dagbag.py:587} INFO - Filling up the DagBag from /opt/airflow/dags/dag_parquet_e_lotes.py
[2024-08-24T20:12:54.317+0000] {logging_mixin.py:190} INFO - [2024-08-24T20:12:54.315+0000] {dagbag.py:386} ERROR - Failed to import: /opt/airflow/dags/dag_parquet_e_lotes.py
Traceback (most recent call last):
  File "/home/airflow/.local/lib/python3.12/site-packages/airflow/models/dagbag.py", line 382, in parse
    loader.exec_module(new_module)
  File "<frozen importlib._bootstrap_external>", line 991, in exec_module
  File "<frozen importlib._bootstrap_external>", line 1129, in get_code
  File "<frozen importlib._bootstrap_external>", line 1059, in source_to_code
  File "<frozen importlib._bootstrap>", line 488, in _call_with_frames_removed
  File "/opt/airflow/dags/dag_parquet_e_lotes.py", line 67
    carregar_no_postgresql_task = PythonOperator(
IndentationError: unexpected indent
[2024-08-24T20:12:54.318+0000] {processor.py:927} WARNING - No viable dags retrieved from /opt/airflow/dags/dag_parquet_e_lotes.py
[2024-08-24T20:12:54.356+0000] {processor.py:208} INFO - Processing /opt/airflow/dags/dag_parquet_e_lotes.py took 0.085 seconds
[2024-08-24T20:13:24.884+0000] {processor.py:186} INFO - Started process (PID=11303) to work on /opt/airflow/dags/dag_parquet_e_lotes.py
[2024-08-24T20:13:24.886+0000] {processor.py:914} INFO - Processing file /opt/airflow/dags/dag_parquet_e_lotes.py for tasks to queue
[2024-08-24T20:13:24.889+0000] {logging_mixin.py:190} INFO - [2024-08-24T20:13:24.888+0000] {dagbag.py:587} INFO - Filling up the DagBag from /opt/airflow/dags/dag_parquet_e_lotes.py
[2024-08-24T20:13:24.920+0000] {logging_mixin.py:190} INFO - [2024-08-24T20:13:24.918+0000] {dagbag.py:386} ERROR - Failed to import: /opt/airflow/dags/dag_parquet_e_lotes.py
Traceback (most recent call last):
  File "/home/airflow/.local/lib/python3.12/site-packages/airflow/models/dagbag.py", line 382, in parse
    loader.exec_module(new_module)
  File "<frozen importlib._bootstrap_external>", line 991, in exec_module
  File "<frozen importlib._bootstrap_external>", line 1129, in get_code
  File "<frozen importlib._bootstrap_external>", line 1059, in source_to_code
  File "<frozen importlib._bootstrap>", line 488, in _call_with_frames_removed
  File "/opt/airflow/dags/dag_parquet_e_lotes.py", line 67
    carregar_no_postgresql_task = PythonOperator(
IndentationError: unexpected indent
[2024-08-24T20:13:24.922+0000] {processor.py:927} WARNING - No viable dags retrieved from /opt/airflow/dags/dag_parquet_e_lotes.py
[2024-08-24T20:13:24.964+0000] {processor.py:208} INFO - Processing /opt/airflow/dags/dag_parquet_e_lotes.py took 0.093 seconds
[2024-08-24T20:13:55.029+0000] {processor.py:186} INFO - Started process (PID=11366) to work on /opt/airflow/dags/dag_parquet_e_lotes.py
[2024-08-24T20:13:55.031+0000] {processor.py:914} INFO - Processing file /opt/airflow/dags/dag_parquet_e_lotes.py for tasks to queue
[2024-08-24T20:13:55.033+0000] {logging_mixin.py:190} INFO - [2024-08-24T20:13:55.032+0000] {dagbag.py:587} INFO - Filling up the DagBag from /opt/airflow/dags/dag_parquet_e_lotes.py
[2024-08-24T20:13:55.058+0000] {logging_mixin.py:190} INFO - [2024-08-24T20:13:55.056+0000] {dagbag.py:386} ERROR - Failed to import: /opt/airflow/dags/dag_parquet_e_lotes.py
Traceback (most recent call last):
  File "/home/airflow/.local/lib/python3.12/site-packages/airflow/models/dagbag.py", line 382, in parse
    loader.exec_module(new_module)
  File "<frozen importlib._bootstrap_external>", line 991, in exec_module
  File "<frozen importlib._bootstrap_external>", line 1129, in get_code
  File "<frozen importlib._bootstrap_external>", line 1059, in source_to_code
  File "<frozen importlib._bootstrap>", line 488, in _call_with_frames_removed
  File "/opt/airflow/dags/dag_parquet_e_lotes.py", line 67
    carregar_no_postgresql_task = PythonOperator(
IndentationError: unexpected indent
[2024-08-24T20:13:55.060+0000] {processor.py:927} WARNING - No viable dags retrieved from /opt/airflow/dags/dag_parquet_e_lotes.py
[2024-08-24T20:13:55.103+0000] {processor.py:208} INFO - Processing /opt/airflow/dags/dag_parquet_e_lotes.py took 0.086 seconds
[2024-08-24T20:14:25.363+0000] {processor.py:186} INFO - Started process (PID=11427) to work on /opt/airflow/dags/dag_parquet_e_lotes.py
[2024-08-24T20:14:25.364+0000] {processor.py:914} INFO - Processing file /opt/airflow/dags/dag_parquet_e_lotes.py for tasks to queue
[2024-08-24T20:14:25.367+0000] {logging_mixin.py:190} INFO - [2024-08-24T20:14:25.366+0000] {dagbag.py:587} INFO - Filling up the DagBag from /opt/airflow/dags/dag_parquet_e_lotes.py
[2024-08-24T20:14:25.395+0000] {logging_mixin.py:190} INFO - [2024-08-24T20:14:25.393+0000] {dagbag.py:386} ERROR - Failed to import: /opt/airflow/dags/dag_parquet_e_lotes.py
Traceback (most recent call last):
  File "/home/airflow/.local/lib/python3.12/site-packages/airflow/models/dagbag.py", line 382, in parse
    loader.exec_module(new_module)
  File "<frozen importlib._bootstrap_external>", line 991, in exec_module
  File "<frozen importlib._bootstrap_external>", line 1129, in get_code
  File "<frozen importlib._bootstrap_external>", line 1059, in source_to_code
  File "<frozen importlib._bootstrap>", line 488, in _call_with_frames_removed
  File "/opt/airflow/dags/dag_parquet_e_lotes.py", line 67
    carregar_no_postgresql_task = PythonOperator(
IndentationError: unexpected indent
[2024-08-24T20:14:25.396+0000] {processor.py:927} WARNING - No viable dags retrieved from /opt/airflow/dags/dag_parquet_e_lotes.py
[2024-08-24T20:14:25.429+0000] {processor.py:208} INFO - Processing /opt/airflow/dags/dag_parquet_e_lotes.py took 0.077 seconds
[2024-08-24T20:14:55.617+0000] {processor.py:186} INFO - Started process (PID=11490) to work on /opt/airflow/dags/dag_parquet_e_lotes.py
[2024-08-24T20:14:55.625+0000] {processor.py:914} INFO - Processing file /opt/airflow/dags/dag_parquet_e_lotes.py for tasks to queue
[2024-08-24T20:14:55.634+0000] {logging_mixin.py:190} INFO - [2024-08-24T20:14:55.633+0000] {dagbag.py:587} INFO - Filling up the DagBag from /opt/airflow/dags/dag_parquet_e_lotes.py
[2024-08-24T20:14:55.690+0000] {logging_mixin.py:190} INFO - [2024-08-24T20:14:55.688+0000] {dagbag.py:386} ERROR - Failed to import: /opt/airflow/dags/dag_parquet_e_lotes.py
Traceback (most recent call last):
  File "/home/airflow/.local/lib/python3.12/site-packages/airflow/models/dagbag.py", line 382, in parse
    loader.exec_module(new_module)
  File "<frozen importlib._bootstrap_external>", line 991, in exec_module
  File "<frozen importlib._bootstrap_external>", line 1129, in get_code
  File "<frozen importlib._bootstrap_external>", line 1059, in source_to_code
  File "<frozen importlib._bootstrap>", line 488, in _call_with_frames_removed
  File "/opt/airflow/dags/dag_parquet_e_lotes.py", line 67
    carregar_no_postgresql_task = PythonOperator(
IndentationError: unexpected indent
[2024-08-24T20:14:55.698+0000] {processor.py:927} WARNING - No viable dags retrieved from /opt/airflow/dags/dag_parquet_e_lotes.py
[2024-08-24T20:14:55.784+0000] {processor.py:208} INFO - Processing /opt/airflow/dags/dag_parquet_e_lotes.py took 0.203 seconds
[2024-08-24T20:15:26.347+0000] {processor.py:186} INFO - Started process (PID=11552) to work on /opt/airflow/dags/dag_parquet_e_lotes.py
[2024-08-24T20:15:26.350+0000] {processor.py:914} INFO - Processing file /opt/airflow/dags/dag_parquet_e_lotes.py for tasks to queue
[2024-08-24T20:15:26.353+0000] {logging_mixin.py:190} INFO - [2024-08-24T20:15:26.352+0000] {dagbag.py:587} INFO - Filling up the DagBag from /opt/airflow/dags/dag_parquet_e_lotes.py
[2024-08-24T20:15:26.391+0000] {logging_mixin.py:190} INFO - [2024-08-24T20:15:26.388+0000] {dagbag.py:386} ERROR - Failed to import: /opt/airflow/dags/dag_parquet_e_lotes.py
Traceback (most recent call last):
  File "/home/airflow/.local/lib/python3.12/site-packages/airflow/models/dagbag.py", line 382, in parse
    loader.exec_module(new_module)
  File "<frozen importlib._bootstrap_external>", line 991, in exec_module
  File "<frozen importlib._bootstrap_external>", line 1129, in get_code
  File "<frozen importlib._bootstrap_external>", line 1059, in source_to_code
  File "<frozen importlib._bootstrap>", line 488, in _call_with_frames_removed
  File "/opt/airflow/dags/dag_parquet_e_lotes.py", line 67
    carregar_no_postgresql_task = PythonOperator(
IndentationError: unexpected indent
[2024-08-24T20:15:26.395+0000] {processor.py:927} WARNING - No viable dags retrieved from /opt/airflow/dags/dag_parquet_e_lotes.py
[2024-08-24T20:15:26.447+0000] {processor.py:208} INFO - Processing /opt/airflow/dags/dag_parquet_e_lotes.py took 0.131 seconds
[2024-08-24T20:15:56.605+0000] {processor.py:186} INFO - Started process (PID=11615) to work on /opt/airflow/dags/dag_parquet_e_lotes.py
[2024-08-24T20:15:56.607+0000] {processor.py:914} INFO - Processing file /opt/airflow/dags/dag_parquet_e_lotes.py for tasks to queue
[2024-08-24T20:15:56.610+0000] {logging_mixin.py:190} INFO - [2024-08-24T20:15:56.610+0000] {dagbag.py:587} INFO - Filling up the DagBag from /opt/airflow/dags/dag_parquet_e_lotes.py
[2024-08-24T20:15:56.639+0000] {logging_mixin.py:190} INFO - [2024-08-24T20:15:56.637+0000] {dagbag.py:386} ERROR - Failed to import: /opt/airflow/dags/dag_parquet_e_lotes.py
Traceback (most recent call last):
  File "/home/airflow/.local/lib/python3.12/site-packages/airflow/models/dagbag.py", line 382, in parse
    loader.exec_module(new_module)
  File "<frozen importlib._bootstrap_external>", line 991, in exec_module
  File "<frozen importlib._bootstrap_external>", line 1129, in get_code
  File "<frozen importlib._bootstrap_external>", line 1059, in source_to_code
  File "<frozen importlib._bootstrap>", line 488, in _call_with_frames_removed
  File "/opt/airflow/dags/dag_parquet_e_lotes.py", line 67
    carregar_no_postgresql_task = PythonOperator(
IndentationError: unexpected indent
[2024-08-24T20:15:56.641+0000] {processor.py:927} WARNING - No viable dags retrieved from /opt/airflow/dags/dag_parquet_e_lotes.py
[2024-08-24T20:15:56.678+0000] {processor.py:208} INFO - Processing /opt/airflow/dags/dag_parquet_e_lotes.py took 0.088 seconds
[2024-08-24T20:16:27.600+0000] {processor.py:186} INFO - Started process (PID=11678) to work on /opt/airflow/dags/dag_parquet_e_lotes.py
[2024-08-24T20:16:27.603+0000] {processor.py:914} INFO - Processing file /opt/airflow/dags/dag_parquet_e_lotes.py for tasks to queue
[2024-08-24T20:16:27.606+0000] {logging_mixin.py:190} INFO - [2024-08-24T20:16:27.606+0000] {dagbag.py:587} INFO - Filling up the DagBag from /opt/airflow/dags/dag_parquet_e_lotes.py
[2024-08-24T20:16:27.656+0000] {logging_mixin.py:190} INFO - [2024-08-24T20:16:27.654+0000] {dagbag.py:386} ERROR - Failed to import: /opt/airflow/dags/dag_parquet_e_lotes.py
Traceback (most recent call last):
  File "/home/airflow/.local/lib/python3.12/site-packages/airflow/models/dagbag.py", line 382, in parse
    loader.exec_module(new_module)
  File "<frozen importlib._bootstrap_external>", line 991, in exec_module
  File "<frozen importlib._bootstrap_external>", line 1129, in get_code
  File "<frozen importlib._bootstrap_external>", line 1059, in source_to_code
  File "<frozen importlib._bootstrap>", line 488, in _call_with_frames_removed
  File "/opt/airflow/dags/dag_parquet_e_lotes.py", line 67
    carregar_no_postgresql_task = PythonOperator(
IndentationError: unexpected indent
[2024-08-24T20:16:27.659+0000] {processor.py:927} WARNING - No viable dags retrieved from /opt/airflow/dags/dag_parquet_e_lotes.py
[2024-08-24T20:16:27.716+0000] {processor.py:208} INFO - Processing /opt/airflow/dags/dag_parquet_e_lotes.py took 0.136 seconds
[2024-08-24T20:16:58.136+0000] {processor.py:186} INFO - Started process (PID=11741) to work on /opt/airflow/dags/dag_parquet_e_lotes.py
[2024-08-24T20:16:58.137+0000] {processor.py:914} INFO - Processing file /opt/airflow/dags/dag_parquet_e_lotes.py for tasks to queue
[2024-08-24T20:16:58.140+0000] {logging_mixin.py:190} INFO - [2024-08-24T20:16:58.139+0000] {dagbag.py:587} INFO - Filling up the DagBag from /opt/airflow/dags/dag_parquet_e_lotes.py
[2024-08-24T20:16:58.173+0000] {logging_mixin.py:190} INFO - [2024-08-24T20:16:58.171+0000] {dagbag.py:386} ERROR - Failed to import: /opt/airflow/dags/dag_parquet_e_lotes.py
Traceback (most recent call last):
  File "/home/airflow/.local/lib/python3.12/site-packages/airflow/models/dagbag.py", line 382, in parse
    loader.exec_module(new_module)
  File "<frozen importlib._bootstrap_external>", line 991, in exec_module
  File "<frozen importlib._bootstrap_external>", line 1129, in get_code
  File "<frozen importlib._bootstrap_external>", line 1059, in source_to_code
  File "<frozen importlib._bootstrap>", line 488, in _call_with_frames_removed
  File "/opt/airflow/dags/dag_parquet_e_lotes.py", line 67
    carregar_no_postgresql_task = PythonOperator(
IndentationError: unexpected indent
[2024-08-24T20:16:58.175+0000] {processor.py:927} WARNING - No viable dags retrieved from /opt/airflow/dags/dag_parquet_e_lotes.py
[2024-08-24T20:16:58.209+0000] {processor.py:208} INFO - Processing /opt/airflow/dags/dag_parquet_e_lotes.py took 0.097 seconds
[2024-08-24T20:17:29.153+0000] {processor.py:186} INFO - Started process (PID=11804) to work on /opt/airflow/dags/dag_parquet_e_lotes.py
[2024-08-24T20:17:29.156+0000] {processor.py:914} INFO - Processing file /opt/airflow/dags/dag_parquet_e_lotes.py for tasks to queue
[2024-08-24T20:17:29.161+0000] {logging_mixin.py:190} INFO - [2024-08-24T20:17:29.161+0000] {dagbag.py:587} INFO - Filling up the DagBag from /opt/airflow/dags/dag_parquet_e_lotes.py
[2024-08-24T20:17:29.234+0000] {logging_mixin.py:190} INFO - [2024-08-24T20:17:29.231+0000] {dagbag.py:386} ERROR - Failed to import: /opt/airflow/dags/dag_parquet_e_lotes.py
Traceback (most recent call last):
  File "/home/airflow/.local/lib/python3.12/site-packages/airflow/models/dagbag.py", line 382, in parse
    loader.exec_module(new_module)
  File "<frozen importlib._bootstrap_external>", line 991, in exec_module
  File "<frozen importlib._bootstrap_external>", line 1129, in get_code
  File "<frozen importlib._bootstrap_external>", line 1059, in source_to_code
  File "<frozen importlib._bootstrap>", line 488, in _call_with_frames_removed
  File "/opt/airflow/dags/dag_parquet_e_lotes.py", line 67
    carregar_no_postgresql_task = PythonOperator(
IndentationError: unexpected indent
[2024-08-24T20:17:29.238+0000] {processor.py:927} WARNING - No viable dags retrieved from /opt/airflow/dags/dag_parquet_e_lotes.py
[2024-08-24T20:17:29.323+0000] {processor.py:208} INFO - Processing /opt/airflow/dags/dag_parquet_e_lotes.py took 0.227 seconds
